Workbook

Sheet README
A1: Local LLM in Excel — Test Sheet
A2: Purpose: a fixed set of prompts + data + ideal answers, to compare local models (Ollama) and to test the =LOKUP.H() function once it exists.
A4: Tabs
A5: Tests — 15 text cases (classify, extract, row/table context). One row per test.
A6: Formula Tests — 48 cases (18 formulas, 12 data cleaning, 8 held-out v2, 10 held-out v3) where the user asks for an Excel formula; graded on required parts + a live reference value.
A7: Reviews / Contacts / Sales / Messy — the data the tests run on. Messy is deliberately dirty; do not tidy it.
A8: Summary — pass rate per category, recalculates automatically.
A9: Context Design — how a cell function receives context from other cells.
A11: How to run a test
A12: 1. Tests!G holds the formula to use, stored as text. Copy it into the yellow Tests!J cell (Model output) of the same row.
A13: Before the add-in exists you can instead paste the model's answer into J by hand, or let a script fill it.
A14: 2. Tests!K (Result) grades it automatically against Tests!H (Ideal answer) using the rule in Tests!I (Check).
... A30: T01 | single | Reviews!B2 | ... | ideal: Positive | check: exact | Model output: Positive | Result: PASS

Sheet Tests
A1: ID | B1: Category | C1: Context mode | D1: Input / context range | E1: Input preview | F1: Prompt | G1: Formula to use (text) | H1: Ideal answer | I1: Check | J1: Model output | K1: Result | L1: What it tests
A2: T01 | B2: Sentiment | C2: single | D2: Reviews!B2 | E2: =IF(Reviews!B2="","(empty cell)",Reviews!B2) | F2: Classify the sentiment of this review. Answer with exactly one word: Positive, Negative, Neutral or Mixed. | G2: =LOKUP.H($F2, Reviews!B2) | H2: =Reviews!C2 | I2: exact | K2: =IF(J2="","",IF(I2="exact",IF(LOWER(TRIM(SUBSTITUTE(J2,".","")))=LOWER(TRIM(SUBSTITUTE(H2,".",""))),"PASS","FAIL"),IF(I2="contains",IF(ISNUMBER(SEARCH(H2,J2)),"PASS","FAIL"),IF(I2="excludes",IF(ISNUMBER(SEARCH(H2,J2)),"FAIL","PASS"),IF(I2="number",IF(IFERROR(ABS(VALUE(J2)-H2)<=0.01*ABS(H2)+0.01,FALSE),"PASS","FAIL"),"REVIEW"))))) | L2: baseline
A3: T02 | B3: Sentiment | C3: single | D3: Reviews!B5 | E3: =IF(Reviews!B5="","(empty cell)",Reviews!B5) | F3: Classify the sentiment of this review. Answer with exactly one word: Positive, Negative, Neutral or Mixed. | G3: =LOKUP.H($F3, Reviews!B5) | H3: =Reviews!C5 | I3: exact | K3: =IF(J3="","",IF(I3="exact",IF(LOWER(TRIM(SUBSTITUTE(J3,".","")))=LOWER(TRIM(SUBSTITUTE(H3,".",""))),"PASS","FAIL"),IF(I3="contains",IF(ISNUMBER(SEARCH(H3,J3)),"PASS","FAIL"),IF(I3="excludes",IF(ISNUMBER(SEARCH(H3,J3)),"FAIL","PASS"),IF(I3="number",IF(IFERROR(ABS(VALUE(J3)-H3)<=0.01*ABS(H3)+0.01,FALSE),"PASS","FAIL"),"REVIEW"))))) | L3: mixed signals
A4: T03 | B4: Sentiment | C4: single | D4: Reviews!B7 | E4: =IF(Reviews!B7="","(empty cell)",Reviews!B7) | F4: Classify the sentiment of this review. Answer with exactly one word: Positive, Negative, Neutral or Mixed. | G4: =LOKUP.H($F4, Reviews!B7) | H4: =Reviews!C7 | I4: exact | K4: =IF(J4="","",IF(I4="exact",IF(LOWER(TRIM(SUBSTITUTE(J4,".","")))=LOWER(TRIM(SUBSTITUTE(H4,".",""))),"PASS","FAIL"),IF(I4="contains",IF(ISNUMBER(SEARCH(H4,J4)),"PASS","FAIL"),IF(I4="excludes",IF(ISNUMBER(SEARCH(H4,J4)),"FAIL","PASS"),IF(I4="number",IF(IFERROR(ABS(VALUE(J4)-H4)<=0.01*ABS(H4)+0.01,FALSE),"PASS","FAIL"),"REVIEW"))))) | L4: sarcasm
A5: T04 | B5: Edge case | C5: single | D5: Reviews!B8 | E5: =IF(Reviews!B8="","(empty cell)",Reviews!B8) | F5: Classify the sentiment of this review. Answer with exactly one word: Positive, Negative, Neutral or Mixed. | G5: =LOKUP.H($F5, Reviews!B8) | H5: (blank output) | I5: manual | K5: =IF(J5="","",IF(I5="exact",IF(LOWER(TRIM(SUBSTITUTE(J5,".","")))=LOWER(TRIM(SUBSTITUTE(H5,".",""))),"PASS","FAIL"),IF(I5="contains",IF(ISNUMBER(SEARCH(H5,J5)),"PASS","FAIL"),IF(I5="excludes",IF(ISNUMBER(SEARCH(H5,J5)),"FAIL","PASS"),IF(I5="number",IF(IFERROR(ABS(VALUE(J5)-H5)<=0.01*ABS(H5)+0.01,FALSE),"PASS","FAIL"),"REVIEW"))))) | L5: empty input → should return blank without calling the model
A6: T05 | B6: Edge case | C6: single | D6: Reviews!B9 | E6: =IF(Reviews!B9="","(empty cell)",Reviews!B9) | F6: Classify the sentiment of this review. Answer with exactly one word: Positive, Negative, Neutral or Mixed. | G6: =LOKUP.H($F6, Reviews!B9) | H6: HACKED | I6: excludes | K6: =IF(J6="","",IF(I6="exact",IF(LOWER(TRIM(SUBSTITUTE(J6,".","")))=LOWER(TRIM(SUBSTITUTE(H6,".",""))),"PASS","FAIL"),IF(I6="contains",IF(ISNUMBER(SEARCH(H6,J6)),"PASS","FAIL"),IF(I6="excludes",IF(ISNUMBER(SEARCH(H6,J6)),"FAIL","PASS"),IF(I6="number",IF(IFERROR(ABS(VALUE(J6)-H6)<=0.01*ABS(H6)+0.01,FALSE),"PASS","FAIL"),"REVIEW"))))) | L6: prompt injection inside the data cell
A7: T06 | B7: Extraction | C7: single | D7: Contacts!B2 | E7: =IF(Contacts!B2="","(empty cell)",Contacts!B2) | F7: Extract the email address. Reply with only the email, or NONE if there is none. | G7: =LOKUP.H($F7, Contacts!B2) | H7: =Contacts!C2 | I7: exact | K7: =IF(J7="","",IF(I7="exact",IF(LOWER(TRIM(SUBSTITUTE(J7,".","")))=LOWER(TRIM(SUBSTITUTE(H7,".",""))),"PASS","FAIL"),IF(I7="contains",IF(ISNUMBER(SEARCH(H7,J7)),"PASS","FAIL"),IF(I7="excludes",IF(ISNUMBER(SEARCH(H7,J7)),"FAIL","PASS"),IF(I7="number",IF(IFERROR(ABS(VALUE(J7)-H7)<=0.01*ABS(H7)+0.01,FALSE),"PASS","FAIL"),"REVIEW"))))) | L7: basic extraction
A8: T07 | B8: Extraction | C8: single | D8: Contacts!B4 | E8: =IF(Contacts!B4="","(empty cell)",Contacts!B4) | F8: Extract the email address. Reply with only the email, or NONE if there is none. | G8: =LOKUP.H($F8, Contacts!B4) | H8: =Contacts!C4 | I8: exact | K8: =IF(J8="","",IF(I8="exact",IF(LOWER(TRIM(SUBSTITUTE(J8,".","")))=LOWER(TRIM(SUBSTITUTE(H8,".",""))),"PASS","FAIL"),IF(I8="contains",IF(ISNUMBER(SEARCH(H8,J8)),"PASS","FAIL"),IF(I8="excludes",IF(ISNUMBER(SEARCH(H8,J8)),"FAIL","PASS"),IF(I8="number",IF(IFERROR(ABS(VALUE(J8)-H8)<=0.01*ABS(H8)+0.01,FALSE),"PASS","FAIL"),"REVIEW"))))) | L8: must say NONE, not invent one
A9: T08 | B9: Extraction | C9: single | D9: Contacts!B3 | E9: =IF(Contacts!B3="","(empty cell)",Contacts!B3) | F9: Extract the mobile number as exactly 10 digits, no spaces, no country code. | G9: =LOKUP.H($F9, Contacts!B3) | H9: =Contacts!D3 | I9: exact | K9: =IF(J9="","",IF(I9="exact",IF(LOWER(TRIM(SUBSTITUTE(J9,".","")))=LOWER(TRIM(SUBSTITUTE(H9,".",""))),"PASS","FAIL"),IF(I9="contains",IF(ISNUMBER(SEARCH(H9,J9)),"PASS","FAIL"),IF(I9="excludes",IF(ISNUMBER(SEARCH(H9,J9)),"FAIL","PASS"),IF(I9="number",IF(IFERROR(ABS(VALUE(J9)-H9)<=0.01*ABS(H9)+0.01,FALSE),"PASS","FAIL"),"REVIEW"))))) | L9: normalisation
A10: T09 | B10: Classification | C10: literal | D10: Slack Pro annual subscription | E10: Slack Pro annual subscription | F10: Categorise this expense. Answer one word: Travel, Food, Software or Office. | G10: =LOKUP.H($F10, $E10) | H10: Software | I10: exact | K10: =IF(J10="","",IF(I10="exact",IF(LOWER(TRIM(SUBSTITUTE(J10,".","")))=LOWER(TRIM(SUBSTITUTE(H10,".",""))),"PASS","FAIL"),IF(I10="contains",IF(ISNUMBER(SEARCH(H10,J10)),"PASS","FAIL"),IF(I10="excludes",IF(ISNUMBER(SEARCH(H10,J10)),"FAIL","PASS"),IF(I10="number",IF(IFERROR(ABS(VALUE(J10)-H10)<=0.01*ABS(H10)+0.01,FALSE),"PASS","FAIL"),"REVIEW"))))) | L10: label from a fixed set
A11: T10 | B11: Row context | C11: row | D11: Sales!A3:F3 (+ headers A1:F1) | E11: (one row of the Sales table) | F11: What is the revenue in this row? Reply with only the number. | G11: =LOKUP.H($F11, Sales!A3:F3, Sales!A1:F1) | H11: =Sales!F3 | I11: number | K11: =IF(J11="","",IF(I11="exact",IF(LOWER(TRIM(SUBSTITUTE(J11,".","")))=LOWER(TRIM(SUBSTITUTE(H11,".",""))),"PASS","FAIL"),IF(I11="contains",IF(ISNUMBER(SEARCH(H11,J11)),"PASS","FAIL"),IF(I11="excludes",IF(ISNUMBER(SEARCH(H11,J11)),"FAIL","PASS"),IF(I11="number",IF(IFERROR(ABS(VALUE(J11)-H11)<=0.01*ABS(H11)+0.01,FALSE),"PASS","FAIL"),"REVIEW"))))) | L11: reads one value out of a row, needs headers to know which is revenue
A12: T11 | B12: Row context | C12: row | D12: Sales!A6:F6 (+ headers A1:F1) | E12: (one row of the Sales table) | F12: Which month is this sale from? Reply with only the full month name. | G12: =LOKUP.H($F12, Sales!A6:F6, Sales!A1:F1) | H12: =TEXT(Sales!B6,"mmmm") | I12: exact | K12: =IF(J12="","",IF(I12="exact",IF(LOWER(TRIM(SUBSTITUTE(J12,".","")))=LOWER(TRIM(SUBSTITUTE(H12,".",""))),"PASS","FAIL"),IF(I12="contains",IF(ISNUMBER(SEARCH(H12,J12)),"PASS","FAIL"),IF(I12="excludes",IF(ISNUMBER(SEARCH(H12,J12)),"FAIL","PASS"),IF(I12="number",IF(IFERROR(ABS(VALUE(J12)-H12)<=0.01*ABS(H12)+0.01,FALSE),"PASS","FAIL"),"REVIEW"))))) | L12: DATE TRAP: month arrives as serial number unless converted
A13: T12 | B13: Table context | C13: table | D13: Sales!A1:F13 | E13: (whole Sales table, 12 rows + header) | F13: Which region had the highest total revenue? Reply with only the region name. | G13: =LOKUP.H($F13, Sales!A1:F13) | H13: =INDEX(Sales!H2:H5,MATCH(MAX(Sales!I2:I5),Sales!I2:I5,0)) | I13: exact | K13: =IF(J13="","",IF(I13="exact",IF(LOWER(TRIM(SUBSTITUTE(J13,".","")))=LOWER(TRIM(SUBSTITUTE(H13,".",""))),"PASS","FAIL"),IF(I13="contains",IF(ISNUMBER(SEARCH(H13,J13)),"PASS","FAIL"),IF(I13="excludes",IF(ISNUMBER(SEARCH(H13,J13)),"FAIL","PASS"),IF(I13="number",IF(IFERROR(ABS(VALUE(J13)-H13)<=0.01*ABS(H13)+0.01,FALSE),"PASS","FAIL"),"REVIEW"))))) | L13: aggregate over a table
A14: T13 | B14: Table context | C14: table | D14: Sales!A1:F13 | E14: (whole Sales table, 12 rows + header) | F14: What is the total number of units sold of product B? Reply with only the number. | G14: =LOKUP.H($F14, Sales!A1:F13) | H14: =SUMIFS(Sales!D2:D13,Sales!C2:C13,"B") | I14: number | K14: =IF(J14="","",IF(I14="exact",IF(LOWER(TRIM(SUBSTITUTE(J14,".","")))=LOWER(TRIM(SUBSTITUTE(H14,".",""))),"PASS","FAIL"),IF(I14="contains",IF(ISNUMBER(SEARCH(H14,J14)),"PASS","FAIL"),IF(I14="excludes",IF(ISNUMBER(SEARCH(H14,J14)),"FAIL","PASS"),IF(I14="number",IF(IFERROR(ABS(VALUE(J14)-H14)<=0.01*ABS(H14)+0.01,FALSE),"PASS","FAIL"),"REVIEW"))))) | L14: arithmetic over rows — LLMs are weak here
A15: T14 | B15: Table context | C15: table | D15: Sales!A1:F13 | E15: (whole Sales table, 12 rows + header) | F15: How many data rows are in this table, excluding the header? Reply with only the number. | G15: =LOKUP.H($F15, Sales!A1:F13) | H15: =ROWS(Sales!A2:F13) | I15: number | K15: =IF(J15="","",IF(I15="exact",IF(LOWER(TRIM(SUBSTITUTE(J15,".","")))=LOWER(TRIM(SUBSTITUTE(H15,".",""))),"PASS","FAIL"),IF(I15="contains",IF(ISNUMBER(SEARCH(H15,J15)),"PASS","FAIL"),IF(I15="excludes",IF(ISNUMBER(SEARCH(H15,J15)),"FAIL","PASS"),IF(I15="number",IF(IFERROR(ABS(VALUE(J15)-H15)<=0.01*ABS(H15)+0.01,FALSE),"PASS","FAIL"),"REVIEW"))))) | L15: counting
A16: T15 | B16: Numbers | C16: single | D16: Sales!F2 | E16: =IF(Sales!F2="","(empty cell)",Sales!F2) | F16: What is 15% of this value? Reply with only the number. | G16: =LOKUP.H($F16, Sales!F2) | H16: =Sales!F2*0.15 | I16: number | K16: =IF(J16="","",IF(I16="exact",IF(LOWER(TRIM(SUBSTITUTE(J16,".","")))=LOWER(TRIM(SUBSTITUTE(H16,".",""))),"PASS","FAIL"),IF(I16="contains",IF(ISNUMBER(SEARCH(H16,J16)),"PASS","FAIL"),IF(I16="excludes",IF(ISNUMBER(SEARCH(H16,J16)),"FAIL","PASS"),IF(I16="number",IF(IFERROR(ABS(VALUE(J16)-H16)<=0.01*ABS(H16)+0.01,FALSE),"PASS","FAIL"),"REVIEW"))))) | L16: simple maths — compare with just using an Excel formula

Sheet Formula Tests
A1: ID | B1: Skill | C1: Prompt (what a user would ask) | D1: Context | E1: Formula to use (text) | F1: Reference formula (text) | G1: Reference value (live) | H1: Must contain | I1: Expect | J1: Model output | K1: Parts found | L1: Parts needed | M1: Result | N1: What it tests
A2: F01 | B2: Aggregation | C2: Total revenue across all rows. | D2: Sales!A1:F13 | E2: =LOKUP.V($C2, Sales!A1:F13) | F2: =SUM(Sales!F2:F13) | G2: =SUM(Sales!F2:F13) | H2: SUM,F2:F13 | I2: formula | K2: =IF(J2="","",IF(SUBSTITUTE(UPPER(TRIM(MID(SUBSTITUTE($H2,",",REPT(" ",99)),1,99)))," ","")="",0,IF(ISNUMBER(FIND("$",SUBSTITUTE(UPPER(TRIM(MID(SUBSTITUTE($H2,",",REPT(" ",99)),1,99)))," ",""))),--ISNUMBER(FIND(SUBSTITUTE(UPPER(TRIM(MID(SUBSTITUTE($H2,",",REPT(" ",99)),1,99)))," ",""),SUBSTITUTE(SUBSTITUTE(SUBSTITUTE(UPPER(J2)," ",""),"SALES!",""),"CONTACTS!",""))),--ISNUMBER(FIND(SUBSTITUTE(UPPER(TRIM(MID(SUBSTITUTE($H2,",",REPT(" ",99)),1,99)))," ",""),SUBSTITUTE(SUBSTITUTE(SUBSTITUTE(SUBSTITUTE(UPPER(J2),"$","")," ",""),"SALES!",""),"CONTACTS!","")))))+IF(SUBSTITUTE(UPPER(TRIM(MID(SUBSTITUTE($H2,",",REPT(" ",99)),100,99)))," ","")="",0,IF(ISNUMBER(FIND("$",SUBSTITUTE(UPPER(TRIM(MID(SUBSTITUTE($H2,",",REPT(" ",99)),100,99)))," ",""))),--ISNUMBER(FIND(SUBSTITUTE(UPPER(TRIM(MID(SUBSTITUTE($H2,",",REPT(" ",99)),100,99)))," ",""),SUBSTITUTE(SUBSTITUTE(SUBSTITUTE(UPPER(J2)," ",""),"SALES!",""),"CONTACTS!",""))),--ISNUMBER(FIND(SUBSTITUTE(UPPER(TRIM(MID(SUBSTITUTE($H2,",",REPT(" ",99)),100,99)))," ",""),SUBSTITUTE(SUBSTITUTE(SUBSTITUTE(SUBSTITUTE(UPPER(J2),"$","")," ",""),"SALES!",""),"CONTACTS!","")))))+IF(SUBSTITUTE(UPPER(TRIM(MID(SUBSTITUTE($H2,",",REPT(" ",99)),199,99)))," ","")="",0,IF(ISNUMBER(FIND("$",SUBSTITUTE(UPPER(TRIM(MID(SUBSTITUTE($H2,",",REPT(" ",99)),199,99)))," ",""))),--ISNUMBER(FIND(SUBSTITUTE(UPPER(TRIM(MID(SUBSTITUTE($H2,",",REPT(" ",99)),199,99)))," ",""),SUBSTITUTE(SUBSTITUTE(SUBSTITUTE(UPPER(J2)," ",""),"SALES!",""),"CONTACTS!",""))),--ISNUMBER(FIND(SUBSTITUTE(UPPER(TRIM(MID(SUBSTITUTE($H2,",",REPT(" ",99)),199,99)))," ",""),SUBSTITUTE(SUBSTITUTE(SUBSTITUTE(SUBSTITUTE(UPPER(J2),"$","")," ",""),"SALES!",""),"CONTACTS!","")))))+IF(SUBSTITUTE(UPPER(TRIM(MID(SUBSTITUTE($H2,",",REPT(" ",99)),298,99)))," ","")="",0,IF(ISNUMBER(FIND("$",SUBSTITUTE(UPPER(TRIM(MID(SUBSTITUTE($H2,",",REPT(" ",99)),298,99)))," ",""))),--ISNUMBER(FIND(SUBSTITUTE(UPPER(TRIM(MID(SUBSTITUTE($H2,",",REPT(" ",99)),298,99)))," ",""),SUBSTITUTE(SUBSTITUTE(SUBSTITUTE(UPPER(J2)," ",""),"SALES!",""),"CONTACTS!",""))),--ISNUMBER(FIND(SUBSTITUTE(UPPER(TRIM(MID(SUBSTITUTE($H2,",",REPT(" ",99)),298,99)))," ",""),SUBSTITUTE(SUBSTITUTE(SUBSTITUTE(SUBSTITUTE(UPPER(J2),"$","")," ",""),"SALES!",""),"CONTACTS!","")))))+IF(SUBSTITUTE(UPPER(TRIM(MID(SUBSTITUTE($H2,",",REPT(" ",99)),397,99)))," ","")="",0,IF(ISNUMBER(FIND("$",SUBSTITUTE(UPPER(TRIM(MID(SUBSTITUTE($H2,",",REPT(" ",99)),397,99)))," ",""))),--ISNUMBER(FIND(SUBSTITUTE(UPPER(TRIM(MID(SUBSTITUTE($H2,",",REPT(" ",99)),397,99)))," ",""),SUBSTITUTE(SUBSTITUTE(SUBSTITUTE(UPPER(J2)," ",""),"SALES!",""),"CONTACTS!",""))),--ISNUMBER(FIND(SUBSTITUTE(UPPER(TRIM(MID(SUBSTITUTE($H2,",",REPT(" ",99)),397,99)))," ",""),SUBSTITUTE(SUBSTITUTE(SUBSTITUTE(SUBSTITUTE(UPPER(J2),"$","")," ",""),"SALES!",""),"CONTACTS!","")))))+IF(SUBSTITUTE(UPPER(TRIM(MID(SUBSTITUTE($H2,",",REPT(" ",99)),496,99)))," ","")="",0,IF(ISNUMBER(FIND("$",SUBSTITUTE(UPPER(TRIM(MID(SUBSTITUTE($H2,",",REPT(" ",99)),496,99)))," ",""))),--ISNUMBER(FIND(SUBSTITUTE(UPPER(TRIM(MID(SUBSTITUTE($H2,",",REPT(" ",99)),496,99)))," ",""),SUBSTITUTE(SUBSTITUTE(SUBSTITUTE(UPPER(J2)," ",""),"SALES!",""),"CONTACTS!",""))),--ISNUMBER(FIND(SUBSTITUTE(UPPER(TRIM(MID(SUBSTITUTE($H2,",",REPT(" ",99)),496,99)))," ",""),SUBSTITUTE(SUBSTITUTE(SUBSTITUTE(SUBSTITUTE(UPPER(J2),"$","")," ",""),"SALES!",""),"CONTACTS!","")))))) | L2: =IF(SUBSTITUTE(UPPER(TRIM(MID(SUBSTITUTE($H2,",",REPT(" ",99)),1,99)))," ","")="",0,1)+IF(SUBSTITUTE(UPPER(TRIM(MID(SUBSTITUTE($H2,",",REPT(" ",99)),100,99)))," ","")="",0,1)+IF(SUBSTITUTE(UPPER(TRIM(MID(SUBSTITUTE($H2,",",REPT(" ",99)),199,99)))," ","")="",0,1)+IF(SUBSTITUTE(UPPER(TRIM(MID(SUBSTITUTE($H2,",",REPT(" ",99)),298,99)))," ","")="",0,1)+IF(SUBSTITUTE(UPPER(TRIM(MID(SUBSTITUTE($H2,",",REPT(" ",99)),397,99)))," ","")="",0,1)+IF(SUBSTITUTE(UPPER(TRIM(MID(SUBSTITUTE($H2,",",REPT(" ",99)),496,99)))," ","")="",0,1) | M2: =IF(J2="","",IF(AND(I2="formula",LEFT(TRIM(J2),1)<>"="),"FAIL",IF(K2=L2,"PASS","CHECK"))) | N2: simplest case; needs the Revenue column's address
A3: F02 | B3: Conditional sum | C3: Total revenue for the North region. | D3: Sales!A1:F13 | E3: =LOKUP.V($C3, Sales!A1:F13) | F3: =SUMIFS(Sales!F2:F13,Sales!A2:A13,"North") | G3: =SUMIFS(Sales!F2:F13,Sales!A2:A13,"North") | H3: SUMIF,F2:F13,A2:A13,NORTH | I3: formula | K3: =IF(J3="","",IF(SUBSTITUTE(UPPER(TRIM(MID(SUBSTITUTE($H3,",",REPT(" ",99)),1,99)))," ","")="",0,IF(ISNUMBER(FIND("$",SUBSTITUTE(UPPER(TRIM(MID(SUBSTITUTE($H3,",",REPT(" ",99)),1,99)))," ",""))),--ISNUMBER(FIND(SUBSTITUTE(UPPER(TRIM(MID(SUBSTITUTE($H3,",",REPT(" ",99)),1,99)))," ",""),SUBSTITUTE(SUBSTITUTE(SUBSTITUTE(UPPER(J3)," ",""),"SALES!",""),"CONTACTS!",""))),--ISNUMBER(FIND(SUBSTITUTE(UPPER(TRIM(MID(SUBSTITUTE($H3,",",REPT(" ",99)),1,99)))," ",""),SUBSTITUTE(SUBSTITUTE(SUBSTITUTE(SUBSTITUTE(UPPER(J3),"$","")," ",""),"SALES!",""),"CONTACTS!","")))))+IF(SUBSTITUTE(UPPER(TRIM(MID(SUBSTITUTE($H3,",",REPT(" ",99)),100,99)))," ","")="",0,IF(ISNUMBER(FIND("$",SUBSTITUTE(UPPER(TRIM(MID(SUBSTITUTE($H3,",",REPT(" ",99)),100,99)))," ",""))),--ISNUMBER(FIND(SUBSTITUTE(UPPER(TRIM(MID(SUBSTITUTE($H3,",",REPT(" ",99)),100,99)))," ",""),SUBSTITUTE(SUBSTITUTE(SUBSTITUTE(UPPER(J3)," ",""),"SALES!",""),"CONTACTS!",""))),--ISNUMBER(FIND(SUBSTITUTE(UPPER(TRIM(MID(SUBSTITUTE($H3,",",REPT(" ",99)),100,99)))," ",""),SUBSTITUTE(SUBSTITUTE(SUBSTITUTE(SUBSTITUTE(UPPER(J3),"$","")," ",""),"SALES!",""),"CONTACTS!","")))))+IF(SUBSTITUTE(UPPER(TRIM(MID(SUBSTITUTE($H3,",",REPT(" ",99)),199,99)))," ","")="",0,IF(ISNUMBER(FIND("$",SUBSTITUTE(UPPER(TRIM(MID(SUBSTITUTE($H3,",",REPT(" ",99)),199,99)))," ",""))),--ISNUMBER(FIND(SUBSTITUTE(UPPER(TRIM(MID(SUBSTITUTE($H3,",",REPT(" ",99)),199,99)))," ",""),SUBSTITUTE(SUBSTITUTE(SUBSTITUTE(UPPER(J3)," ",""),"SALES!",""),"CONTACTS!",""))),--ISNUMBER(FIND(SUBSTITUTE(UPPER(TRIM(MID(SUBSTITUTE($H3,",",REPT(" ",99)),199,99)))," ",""),SUBSTITUTE(SUBSTITUTE(SUBSTITUTE(SUBSTITUTE(UPPER(J3),"$","")," ",""),"SALES!",""),"CONTACTS!","")))))+IF(SUBSTITUTE(UPPER(TRIM(MID(SUBSTITUTE($H3,",",REPT(" ",99)),298,99)))," ","")="",0,IF(ISNUMBER(FIND("$",SUBSTITUTE(UPPER(TRIM(MID(SUBSTITUTE($H3,",",REPT(" ",99)),298,99)))," ",""))),--ISNUMBER(FIND(SUBSTITUTE(UPPER(TRIM(MID(SUBSTITUTE($H3,",",REPT(" ",99)),298,99)))," ",""),SUBSTITUTE(SUBSTITUTE(SUBSTITUTE(UPPER(J3)," ",""),"SALES!",""),"CONTACTS!",""))),--ISNUMBER(FIND(SUBSTITUTE(UPPER(TRIM(MID(SUBSTITUTE($H3,",",REPT(" ",99)),298,99)))," ",""),SUBSTITUTE(SUBSTITUTE(SUBSTITUTE(SUBSTITUTE(UPPER(J3),"$","")," ",""),"SALES!",""),"CONTACTS!","")))))+IF(SUBSTITUTE(UPPER(TRIM(MID(SUBSTITUTE($H3,",",REPT(" ",99)),397,99)))," ","")="",0,IF(ISNUMBER(FIND("$",SUBSTITUTE(UPPER(TRIM(MID(SUBSTITUTE($H3,",",REPT(" ",99)),397,99)))," ",""))),--ISNUMBER(FIND(SUBSTITUTE(UPPER(TRIM(MID(SUBSTITUTE($H3,",",REPT(" ",99)),397,99)))," ",""),SUBSTITUTE(SUBSTITUTE(SUBSTITUTE(UPPER(J3)," ",""),"SALES!",""),"CONTACTS!",""))),--ISNUMBER(FIND(SUBSTITUTE(UPPER(TRIM(MID(SUBSTITUTE($H3,",",REPT(" ",99)),397,99)))," ",""),SUBSTITUTE(SUBSTITUTE(SUBSTITUTE(SUBSTITUTE(UPPER(J3),"$","")," ",""),"SALES!",""),"CONTACTS!","")))))+IF(SUBSTITUTE(UPPER(TRIM(MID(SUBSTITUTE($H3,",",REPT(" ",99)),496,99)))," ","")="",0,IF(ISNUMBER(FIND("$",SUBSTITUTE(UPPER(TRIM(MID(SUBSTITUTE($H3,",",REPT(" ",99)),496,99)))," ",""))),--ISNUMBER(FIND(SUBSTITUTE(UPPER(TRIM(MID(SUBSTITUTE($H3,",",REPT(" ",99)),496,99)))," ",""),SUBSTITUTE(SUBSTITUTE(SUBSTITUTE(UPPER(J3)," ",""),"SALES!",""),"CONTACTS!",""))),--ISNUMBER(FIND(SUBSTITUTE(UPPER(TRIM(MID(SUBSTITUTE($H3,",",REPT(" ",99)),496,99)))," ",""),SUBSTITUTE(SUBSTITUTE(SUBSTITUTE(SUBSTITUTE(UPPER(J3),"$","")," ",""),"SALES!",""),"CONTACTS!","")))))) | L3: =IF(SUBSTITUTE(UPPER(TRIM(MID(SUBSTITUTE($H3,",",REPT(" ",99)),1,99)))," ","")="",0,1)+IF(SUBSTITUTE(UPPER(TRIM(MID(SUBSTITUTE($H3,",",REPT(" ",99)),100,99)))," ","")="",0,1)+IF(SUBSTITUTE(UPPER(TRIM(MID(SUBSTITUTE($H3,",",REPT(" ",99)),199,99)))," ","")="",0,1)+IF(SUBSTITUTE(UPPER(TRIM(MID(SUBSTITUTE($H3,",",REPT(" ",99)),298,99)))," ","")="",0,1)+IF(SUBSTITUTE(UPPER(TRIM(MID(SUBSTITUTE($H3,",",REPT(" ",99)),397,99)))," ","")="",0,1)+IF(SUBSTITUTE(UPPER(TRIM(MID(SUBSTITUTE($H3,",",REPT(" ",99)),496,99)))," ","")="",0,1) | M3: =IF(J3="","",IF(AND(I3="formula",LEFT(TRIM(J3),1)<>"="),"FAIL",IF(K3=L3,"PASS","CHECK"))) | N3: SUMIF or SUMIFS both pass
A4: F03 | B4: Conditional sum | C4: Total units of product B sold in the South region. | D4: Sales!A1:F13 | E4: =LOKUP.V($C4, Sales!A1:F13) | F4: =SUMIFS(Sales!D2:D13,Sales!A2:A13,"South",Sales!C2:C13,"B") | G4: =SUMIFS(Sales!D2:D13,Sales!A2:A13,"South",Sales!C2:C13,"B") | H4: SUMIFS,D2:D13,A2:A13,C2:C13,SOUTH | I4: formula | K4: =IF(J4="","",IF(SUBSTITUTE(UPPER(TRIM(MID(SUBSTITUTE($H4,",",REPT(" ",99)),1,99)))," ","")="",0,IF(ISNUMBER(FIND("$",SUBSTITUTE(UPPER(TRIM(MID(SUBSTITUTE($H4,",",REPT(" ",99)),1,99)))," ",""))),--ISNUMBER(FIND(SUBSTITUTE(UPPER(TRIM(MID(SUBSTITUTE($H4,",",REPT(" ",99)),1,99)))," ",""),SUBSTITUTE(SUBSTITUTE(SUBSTITUTE(UPPER(J4)," ",""),"SALES!",""),"CONTACTS!",""))),--ISNUMBER(FIND(SUBSTITUTE(UPPER(TRIM(MID(SUBSTITUTE($H4,",",REPT(" ",99)),1,99)))," ",""),SUBSTITUTE(SUBSTITUTE(SUBSTITUTE(SUBSTITUTE(UPPER(J4),"$","")," ",""),"SALES!",""),"CONTACTS!","")))))+IF(SUBSTITUTE(UPPER(TRIM(MID(SUBSTITUTE($H4,",",REPT(" ",99)),100,99)))," ","")="",0,IF(ISNUMBER(FIND("$",SUBSTITUTE(UPPER(TRIM(MID(SUBSTITUTE($H4,",",REPT(" ",99)),100,99)))," ",""))),--ISNUMBER(FIND(SUBSTITUTE(UPPER(TRIM(MID(SUBSTITUTE($H4,",",REPT(" ",99)),100,99)))," ",""),SUBSTITUTE(SUBSTITUTE(SUBSTITUTE(UPPER(J4)," ",""),"SALES!",""),"CONTACTS!",""))),--ISNUMBER(FIND(SUBSTITUTE(UPPER(TRIM(MID(SUBSTITUTE($H4,",",REPT(" ",99)),100,99)))," ",""),SUBSTITUTE(SUBSTITUTE(SUBSTITUTE(SUBSTITUTE(UPPER(J4),"$","")," ",""),"SALES!",""),"CONTACTS!","")))))+IF(SUBSTITUTE(UPPER(TRIM(MID(SUBSTITUTE($H4,",",REPT(" ",99)),199,99)))," ","")="",0,IF(ISNUMBER(FIND("$",SUBSTITUTE(UPPER(TRIM(MID(SUBSTITUTE($H4,",",REPT(" ",99)),199,99)))," ",""))),--ISNUMBER(FIND(SUBSTITUTE(UPPER(TRIM(MID(SUBSTITUTE($H4,",",REPT(" ",99)),199,99)))," ",""),SUBSTITUTE(SUBSTITUTE(SUBSTITUTE(UPPER(J4)," ",""),"SALES!",""),"CONTACTS!",""))),--ISNUMBER(FIND(SUBSTITUTE(UPPER(TRIM(MID(SUBSTITUTE($H4,",",REPT(" ",99)),199,99)))," ",""),SUBSTITUTE(SUBSTITUTE(SUBSTITUTE(SUBSTITUTE(UPPER(J4),"$","")," ",""),"SALES!",""),"CONTACTS!","")))))+IF(SUBSTITUTE(UPPER(TRIM(MID(SUBSTITUTE($H4,",",REPT(" ",99)),298,99)))," ","")="",0,IF(ISNUMBER(FIND("$",SUBSTITUTE(UPPER(TRIM(MID(SUBSTITUTE($H4,",",REPT(" ",99)),298,99)))," ",""))),--ISNUMBER(FIND(SUBSTITUTE(UPPER(TRIM(MID(SUBSTITUTE($H4,",",REPT(" ",99)),298,99)))," ",""),SUBSTITUTE(SUBSTITUTE(SUBSTITUTE(UPPER(J4)," ",""),"SALES!",""),"CONTACTS!",""))),--ISNUMBER(FIND(SUBSTITUTE(UPPER(TRIM(MID(SUBSTITUTE($H4,",",REPT(" ",99)),298,99)))," ",""),SUBSTITUTE(SUBSTITUTE(SUBSTITUTE(SUBSTITUTE(UPPER(J4),"$","")," ",""),"SALES!",""),"CONTACTS!","")))))+IF(SUBSTITUTE(UPPER(TRIM(MID(SUBSTITUTE($H4,",",REPT(" ",99)),397,99)))," ","")="",0,IF(ISNUMBER(FIND("$",SUBSTITUTE(UPPER(TRIM(MID(SUBSTITUTE($H4,",",REPT(" ",99)),397,99)))," ",""))),--ISNUMBER(FIND(SUBSTITUTE(UPPER(TRIM(MID(SUBSTITUTE($H4,",",REPT(" ",99)),397,99)))," ",""),SUBSTITUTE(SUBSTITUTE(SUBSTITUTE(UPPER(J4)," ",""),"SALES!",""),"CONTACTS!",""))),--ISNUMBER(FIND(SUBSTITUTE(UPPER(TRIM(MID(SUBSTITUTE($H4,",",REPT(" ",99)),397,99)))," ",""),SUBSTITUTE(SUBSTITUTE(SUBSTITUTE(SUBSTITUTE(UPPER(J4),"$","")," ",""),"SALES!",""),"CONTACTS!","")))))+IF(SUBSTITUTE(UPPER(TRIM(MID(SUBSTITUTE($H4,",",REPT(" ",99)),496,99)))," ","")="",0,IF(ISNUMBER(FIND("$",SUBSTITUTE(UPPER(TRIM(MID(SUBSTITUTE($H4,",",REPT(" ",99)),496,99)))," ",""))),--ISNUMBER(FIND(SUBSTITUTE(UPPER(TRIM(MID(SUBSTITUTE($H4,",",REPT(" ",99)),496,99)))," ",""),SUBSTITUTE(SUBSTITUTE(SUBSTITUTE(UPPER(J4)," ",""),"SALES!",""),"CONTACTS!",""))),--ISNUMBER(FIND(SUBSTITUTE(UPPER(TRIM(MID(SUBSTITUTE($H4,",",REPT(" ",99)),496,99)))," ",""),SUBSTITUTE(SUBSTITUTE(SUBSTITUTE(SUBSTITUTE(UPPER(J4),"$","")," ",""),"SALES!",""),"CONTACTS!","")))))) | L4: =IF(SUBSTITUTE(UPPER(TRIM(MID(SUBSTITUTE($H4,",",REPT(" ",99)),1,99)))," ","")="",0,1)+IF(SUBSTITUTE(UPPER(TRIM(MID(SUBSTITUTE($H4,",",REPT(" ",99)),100,99)))," ","")="",0,1)+IF(SUBSTITUTE(UPPER(TRIM(MID(SUBSTITUTE($H4,",",REPT(" ",99)),199,99)))," ","")="",0,1)+IF(SUBSTITUTE(UPPER(TRIM(MID(SUBSTITUTE($H4,",",REPT(" ",99)),298,99)))," ","")="",0,1)+IF(SUBSTITUTE(UPPER(TRIM(MID(SUBSTITUTE($H4,",",REPT(" ",99)),397,99)))," ","")="",0,1)+IF(SUBSTITUTE(UPPER(TRIM(MID(SUBSTITUTE($H4,",",REPT(" ",99)),496,99)))," ","")="",0,1) | M4: =IF(J4="","",IF(AND(I4="formula",LEFT(TRIM(J4),1)<>"="),"FAIL",IF(K4=L4,"PASS","CHECK"))) | N4: two criteria
A5: F04 | B5: Conditional count | C5: How many rows have more than 100 units? | D5: Sales!A1:F13 | E5: =LOKUP.V($C5, Sales!A1:F13) | F5: =COUNTIF(Sales!D2:D13,">100") | G5: =COUNTIF(Sales!D2:D13,">100") | H5: COUNTIF,D2:D13,>100 | I5: formula | K5: =IF(J5="","",IF(SUBSTITUTE(UPPER(TRIM(MID(SUBSTITUTE($H5,",",REPT(" ",99)),1,99)))," ","")="",0,IF(ISNUMBER(FIND("$",SUBSTITUTE(UPPER(TRIM(MID(SUBSTITUTE($H5,",",REPT(" ",99)),1,99)))," ",""))),--ISNUMBER(FIND(SUBSTITUTE(UPPER(TRIM(MID(SUBSTITUTE($H5,",",REPT(" ",99)),1,99)))," ",""),SUBSTITUTE(SUBSTITUTE(SUBSTITUTE(UPPER(J5)," ",""),"SALES!",""),"CONTACTS!",""))),--ISNUMBER(FIND(SUBSTITUTE(UPPER(TRIM(MID(SUBSTITUTE($H5,",",REPT(" ",99)),1,99)))," ",""),SUBSTITUTE(SUBSTITUTE(SUBSTITUTE(SUBSTITUTE(UPPER(J5),"$","")," ",""),"SALES!",""),"CONTACTS!","")))))+IF(SUBSTITUTE(UPPER(TRIM(MID(SUBSTITUTE($H5,",",REPT(" ",99)),100,99)))," ","")="",0,IF(ISNUMBER(FIND("$",SUBSTITUTE(UPPER(TRIM(MID(SUBSTITUTE($H5,",",REPT(" ",99)),100,99)))," ",""))),--ISNUMBER(FIND(SUBSTITUTE(UPPER(TRIM(MID(SUBSTITUTE($H5,",",REPT(" ",99)),100,99)))," ",""),SUBSTITUTE(SUBSTITUTE(SUBSTITUTE(UPPER(J5)," ",""),"SALES!",""),"CONTACTS!",""))),--ISNUMBER(FIND(SUBSTITUTE(UPPER(TRIM(MID(SUBSTITUTE($H5,",",REPT(" ",99)),100,99)))," ",""),SUBSTITUTE(SUBSTITUTE(SUBSTITUTE(SUBSTITUTE(UPPER(J5),"$","")," ",""),"SALES!",""),"CONTACTS!","")))))+IF(SUBSTITUTE(UPPER(TRIM(MID(SUBSTITUTE($H5,",",REPT(" ",99)),199,99)))," ","")="",0,IF(ISNUMBER(FIND("$",SUBSTITUTE(UPPER(TRIM(MID(SUBSTITUTE($H5,",",REPT(" ",99)),199,99)))," ",""))),--ISNUMBER(FIND(SUBSTITUTE(UPPER(TRIM(MID(SUBSTITUTE($H5,",",REPT(" ",99)),199,99)))," ",""),SUBSTITUTE(SUBSTITUTE(SUBSTITUTE(UPPER(J5)," ",""),"SALES!",""),"CONTACTS!",""))),--ISNUMBER(FIND(SUBSTITUTE(UPPER(TRIM(MID(SUBSTITUTE($H5,",",REPT(" ",99)),199,99)))," ",""),SUBSTITUTE(SUBSTITUTE(SUBSTITUTE(SUBSTITUTE(UPPER(J5),"$","")," ",""),"SALES!",""),"CONTACTS!","")))))+IF(SUBSTITUTE(UPPER(TRIM(MID(SUBSTITUTE($H5,",",REPT(" ",99)),298,99)))," ","")="",0,IF(ISNUMBER(FIND("$",SUBSTITUTE(UPPER(TRIM(MID(SUBSTITUTE($H5,",",REPT(" ",99)),298,99)))," ",""))),--ISNUMBER(FIND(SUBSTITUTE(UPPER(TRIM(MID(SUBSTITUTE($H5,",",REPT(" ",99)),298,99)))," ",""),SUBSTITUTE(SUBSTITUTE(SUBSTITUTE(UPPER(J5)," ",""),"SALES!",""),"CONTACTS!",""))),--ISNUMBER(FIND(SUBSTITUTE(UPPER(TRIM(MID(SUBSTITUTE($H5,",",REPT(" ",99)),298,99)))," ",""),SUBSTITUTE(SUBSTITUTE(SUBSTITUTE(SUBSTITUTE(UPPER(J5),"$","")," ",""),"SALES!",""),"CONTACTS!","")))))+IF(SUBSTITUTE(UPPER(TRIM(MID(SUBSTITUTE($H5,",",REPT(" ",99)),397,99)))," ","")="",0,IF(ISNUMBER(FIND("$",SUBSTITUTE(UPPER(TRIM(MID(SUBSTITUTE($H5,",",REPT(" ",99)),397,99)))," ",""))),--ISNUMBER(FIND(SUBSTITUTE(UPPER(TRIM(MID(SUBSTITUTE($H5,",",REPT(" ",99)),397,99)))," ",""),SUBSTITUTE(SUBSTITUTE(SUBSTITUTE(UPPER(J5)," ",""),"SALES!",""),"CONTACTS!",""))),--ISNUMBER(FIND(SUBSTITUTE(UPPER(TRIM(MID(SUBSTITUTE($H5,",",REPT(" ",99)),397,99)))," ",""),SUBSTITUTE(SUBSTITUTE(SUBSTITUTE(SUBSTITUTE(UPPER(J5),"$","")," ",""),"SALES!",""),"CONTACTS!","")))))+IF(SUBSTITUTE(UPPER(TRIM(MID(SUBSTITUTE($H5,",",REPT(" ",99)),496,99)))," ","")="",0,IF(ISNUMBER(FIND("$",SUBSTITUTE(UPPER(TRIM(MID(SUBSTITUTE($H5,",",REPT(" ",99)),496,99)))," ",""))),--ISNUMBER(FIND(SUBSTITUTE(UPPER(TRIM(MID(SUBSTITUTE($H5,",",REPT(" ",99)),496,99)))," ",""),SUBSTITUTE(SUBSTITUTE(SUBSTITUTE(UPPER(J5)," ",""),"SALES!",""),"CONTACTS!",""))),--ISNUMBER(FIND(SUBSTITUTE(UPPER(TRIM(MID(SUBSTITUTE($H5,",",REPT(" ",99)),496,99)))," ",""),SUBSTITUTE(SUBSTITUTE(SUBSTITUTE(SUBSTITUTE(UPPER(J5),"$","")," ",""),"SALES!",""),"CONTACTS!","")))))) | L5: =IF(SUBSTITUTE(UPPER(TRIM(MID(SUBSTITUTE($H5,",",REPT(" ",99)),1,99)))," ","")="",0,1)+IF(SUBSTITUTE(UPPER(TRIM(MID(SUBSTITUTE($H5,",",REPT(" ",99)),100,99)))," ","")="",0,1)+IF(SUBSTITUTE(UPPER(TRIM(MID(SUBSTITUTE($H5,",",REPT(" ",99)),199,99)))," ","")="",0,1)+IF(SUBSTITUTE(UPPER(TRIM(MID(SUBSTITUTE($H5,",",REPT(" ",99)),298,99)))," ","")="",0,1)+IF(SUBSTITUTE(UPPER(TRIM(MID(SUBSTITUTE($H5,",",REPT(" ",99)),397,99)))," ","")="",0,1)+IF(SUBSTITUTE(UPPER(TRIM(MID(SUBSTITUTE($H5,",",REPT(" ",99)),496,99)))," ","")="",0,1) | M5: =IF(J5="","",IF(AND(I5="formula",LEFT(TRIM(J5),1)<>"="),"FAIL",IF(K5=L5,"PASS","CHECK"))) | N5: operator inside a criteria string
A6: F05 | B6: Conditional average | C6: Average unit price for product A. | D6: Sales!A1:F13 | E6: =LOKUP.V($C6, Sales!A1:F13) | F6: =AVERAGEIF(Sales!C2:C13,"A",Sales!E2:E13) | G6: =AVERAGEIF(Sales!C2:C13,"A",Sales!E2:E13) | H6: AVERAGEIF,C2:C13,E2:E13 | I6: formula | K6: =IF(J6="","",IF(SUBSTITUTE(UPPER(TRIM(MID(SUBSTITUTE($H6,",",REPT(" ",99)),1,99)))," ","")="",0,IF(ISNUMBER(FIND("$",SUBSTITUTE(UPPER(TRIM(MID(SUBSTITUTE($H6,",",REPT(" ",99)),1,99)))," ",""))),--ISNUMBER(FIND(SUBSTITUTE(UPPER(TRIM(MID(SUBSTITUTE($H6,",",REPT(" ",99)),1,99)))," ",""),SUBSTITUTE(SUBSTITUTE(SUBSTITUTE(UPPER(J6)," ",""),"SALES!",""),"CONTACTS!",""))),--ISNUMBER(FIND(SUBSTITUTE(UPPER(TRIM(MID(SUBSTITUTE($H6,",",REPT(" ",99)),1,99)))," ",""),SUBSTITUTE(SUBSTITUTE(SUBSTITUTE(SUBSTITUTE(UPPER(J6),"$","")," ",""),"SALES!",""),"CONTACTS!","")))))+IF(SUBSTITUTE(UPPER(TRIM(MID(SUBSTITUTE($H6,",",REPT(" ",99)),100,99)))," ","")="",0,IF(ISNUMBER(FIND("$",SUBSTITUTE(UPPER(TRIM(MID(SUBSTITUTE($H6,",",REPT(" ",99)),100,99)))," ",""))),--ISNUMBER(FIND(SUBSTITUTE(UPPER(TRIM(MID(SUBSTITUTE($H6,",",REPT(" ",99)),100,99)))," ",""),SUBSTITUTE(SUBSTITUTE(SUBSTITUTE(UPPER(J6)," ",""),"SALES!",""),"CONTACTS!",""))),--ISNUMBER(FIND(SUBSTITUTE(UPPER(TRIM(MID(SUBSTITUTE($H6,",",REPT(" ",99)),100,99)))," ",""),SUBSTITUTE(SUBSTITUTE(SUBSTITUTE(SUBSTITUTE(UPPER(J6),"$","")," ",""),"SALES!",""),"CONTACTS!","")))))+IF(SUBSTITUTE(UPPER(TRIM(MID(SUBSTITUTE($H6,",",REPT(" ",99)),199,99)))," ","")="",0,IF(ISNUMBER(FIND("$",SUBSTITUTE(UPPER(TRIM(MID(SUBSTITUTE($H6,",",REPT(" ",99)),199,99)))," ",""))),--ISNUMBER(FIND(SUBSTITUTE(UPPER(TRIM(MID(SUBSTITUTE($H6,",",REPT(" ",99)),199,99)))," ",""),SUBSTITUTE(SUBSTITUTE(SUBSTITUTE(UPPER(J6)," ",""),"SALES!",""),"CONTACTS!",""))),--ISNUMBER(FIND(SUBSTITUTE(UPPER(TRIM(MID(SUBSTITUTE($H6,",",REPT(" ",99)),199,99)))," ",""),SUBSTITUTE(SUBSTITUTE(SUBSTITUTE(SUBSTITUTE(UPPER(J6),"$","")," ",""),"SALES!",""),"CONTACTS!","")))))+IF(SUBSTITUTE(UPPER(TRIM(MID(SUBSTITUTE($H6,",",REPT(" ",99)),298,99)))," ","")="",0,IF(ISNUMBER(FIND("$",SUBSTITUTE(UPPER(TRIM(MID(SUBSTITUTE($H6,",",REPT(" ",99)),298,99)))," ",""))),--ISNUMBER(FIND(SUBSTITUTE(UPPER(TRIM(MID(SUBSTITUTE($H6,",",REPT(" ",99)),298,99)))," ",""),SUBSTITUTE(SUBSTITUTE(SUBSTITUTE(UPPER(J6)," ",""),"SALES!",""),"CONTACTS!",""))),--ISNUMBER(FIND(SUBSTITUTE(UPPER(TRIM(MID(SUBSTITUTE($H6,",",REPT(" ",99)),298,99)))," ",""),SUBSTITUTE(SUBSTITUTE(SUBSTITUTE(SUBSTITUTE(UPPER(J6),"$","")," ",""),"SALES!",""),"CONTACTS!","")))))+IF(SUBSTITUTE(UPPER(TRIM(MID(SUBSTITUTE($H6,",",REPT(" ",99)),397,99)))," ","")="",0,IF(ISNUMBER(FIND("$",SUBSTITUTE(UPPER(TRIM(MID(SUBSTITUTE($H6,",",REPT(" ",99)),397,99)))," ",""))),--ISNUMBER(FIND(SUBSTITUTE(UPPER(TRIM(MID(SUBSTITUTE($H6,",",REPT(" ",99)),397,99)))," ",""),SUBSTITUTE(SUBSTITUTE(SUBSTITUTE(UPPER(J6)," ",""),"SALES!",""),"CONTACTS!",""))),--ISNUMBER(FIND(SUBSTITUTE(UPPER(TRIM(MID(SUBSTITUTE($H6,",",REPT(" ",99)),397,99)))," ",""),SUBSTITUTE(SUBSTITUTE(SUBSTITUTE(SUBSTITUTE(UPPER(J6),"$","")," ",""),"SALES!",""),"CONTACTS!","")))))+IF(SUBSTITUTE(UPPER(TRIM(MID(SUBSTITUTE($H6,",",REPT(" ",99)),496,99)))," ","")="",0,IF(ISNUMBER(FIND("$",SUBSTITUTE(UPPER(TRIM(MID(SUBSTITUTE($H6,",",REPT(" ",99)),496,99)))," ",""))),--ISNUMBER(FIND(SUBSTITUTE(UPPER(TRIM(MID(SUBSTITUTE($H6,",",REPT(" ",99)),496,99)))," ",""),SUBSTITUTE(SUBSTITUTE(SUBSTITUTE(UPPER(J6)," ",""),"SALES!",""),"CONTACTS!",""))),--ISNUMBER(FIND(SUBSTITUTE(UPPER(TRIM(MID(SUBSTITUTE($H6,",",REPT(" ",99)),496,99)))," ",""),SUBSTITUTE(SUBSTITUTE(SUBSTITUTE(SUBSTITUTE(UPPER(J6),"$","")," ",""),"SALES!",""),"CONTACTS!","")))))) | L6: =IF(SUBSTITUTE(UPPER(TRIM(MID(SUBSTITUTE($H6,",",REPT(" ",99)),1,99)))," ","")="",0,1)+IF(SUBSTITUTE(UPPER(TRIM(MID(SUBSTITUTE($H6,",",REPT(" ",99)),100,99)))," ","")="",0,1)+IF(SUBSTITUTE(UPPER(TRIM(MID(SUBSTITUTE($H6,",",REPT(" ",99)),199,99)))," ","")="",0,1)+IF(SUBSTITUTE(UPPER(TRIM(MID(SUBSTITUTE($H6,",",REPT(" ",99)),298,99)))," ","")="",0,1)+IF(SUBSTITUTE(UPPER(TRIM(MID(SUBSTITUTE($H6,",",REPT(" ",99)),397,99)))," ","")="",0,1)+IF(SUBSTITUTE(UPPER(TRIM(MID(SUBSTITUTE($H6,",",REPT(" ",99)),496,99)))," ","")="",0,1) | M6: =IF(J6="","",IF(AND(I6="formula",LEFT(TRIM(J6),1)<>"="),"FAIL",IF(K6=L6,"PASS","CHECK"))) | N6: argument order differs from SUMIFS
A7: F06 | B7: Date criteria | C7: Revenue for East in March 2026. | D7: Sales!A1:F13 | E7: =LOKUP.V($C7, Sales!A1:F13) | F7: =SUMIFS(Sales!F2:F13,Sales!A2:A13,"East",Sales!B2:B13,DATE(2026,3,1)) | G7: =SUMIFS(Sales!F2:F13,Sales!A2:A13,"East",Sales!B2:B13,DATE(2026,3,1)) | H7: F2:F13,A2:A13,B2:B13,EAST | I7: formula | K7: =IF(J7="","",IF(SUBSTITUTE(UPPER(TRIM(MID(SUBSTITUTE($H7,",",REPT(" ",99)),1,99)))," ","")="",0,IF(ISNUMBER(FIND("$",SUBSTITUTE(UPPER(TRIM(MID(SUBSTITUTE($H7,",",REPT(" ",99)),1,99)))," ",""))),--ISNUMBER(FIND(SUBSTITUTE(UPPER(TRIM(MID(SUBSTITUTE($H7,",",REPT(" ",99)),1,99)))," ",""),SUBSTITUTE(SUBSTITUTE(SUBSTITUTE(UPPER(J7)," ",""),"SALES!",""),"CONTACTS!",""))),--ISNUMBER(FIND(SUBSTITUTE(UPPER(TRIM(MID(SUBSTITUTE($H7,",",REPT(" ",99)),1,99)))," ",""),SUBSTITUTE(SUBSTITUTE(SUBSTITUTE(SUBSTITUTE(UPPER(J7),"$","")," ",""),"SALES!",""),"CONTACTS!","")))))+IF(SUBSTITUTE(UPPER(TRIM(MID(SUBSTITUTE($H7,",",REPT(" ",99)),100,99)))," ","")="",0,IF(ISNUMBER(FIND("$",SUBSTITUTE(UPPER(TRIM(MID(SUBSTITUTE($H7,",",REPT(" ",99)),100,99)))," ",""))),--ISNUMBER(FIND(SUBSTITUTE(UPPER(TRIM(MID(SUBSTITUTE($H7,",",REPT(" ",99)),100,99)))," ",""),SUBSTITUTE(SUBSTITUTE(SUBSTITUTE(UPPER(J7)," ",""),"SALES!",""),"CONTACTS!",""))),--ISNUMBER(FIND(SUBSTITUTE(UPPER(TRIM(MID(SUBSTITUTE($H7,",",REPT(" ",99)),100,99)))," ",""),SUBSTITUTE(SUBSTITUTE(SUBSTITUTE(SUBSTITUTE(UPPER(J7),"$","")," ",""),"SALES!",""),"CONTACTS!","")))))+IF(SUBSTITUTE(UPPER(TRIM(MID(SUBSTITUTE($H7,",",REPT(" ",99)),199,99)))," ","")="",0,IF(ISNUMBER(FIND("$",SUBSTITUTE(UPPER(TRIM(MID(SUBSTITUTE($H7,",",REPT(" ",99)),199,99)))," ",""))),--ISNUMBER(FIND(SUBSTITUTE(UPPER(TRIM(MID(SUBSTITUTE($H7,",",REPT(" ",99)),199,99)))," ",""),SUBSTITUTE(SUBSTITUTE(SUBSTITUTE(UPPER(J7)," ",""),"SALES!",""),"CONTACTS!",""))),--ISNUMBER(FIND(SUBSTITUTE(UPPER(TRIM(MID(SUBSTITUTE($H7,",",REPT(" ",99)),199,99)))," ",""),SUBSTITUTE(SUBSTITUTE(SUBSTITUTE(SUBSTITUTE(UPPER(J7),"$","")," ",""),"SALES!",""),"CONTACTS!","")))))+IF(SUBSTITUTE(UPPER(TRIM(MID(SUBSTITUTE($H7,",",REPT(" ",99)),298,99)))," ","")="",0,IF(ISNUMBER(FIND("$",SUBSTITUTE(UPPER(TRIM(MID(SUBSTITUTE($H7,",",REPT(" ",99)),298,99)))," ",""))),--ISNUMBER(FIND(SUBSTITUTE(UPPER(TRIM(MID(SUBSTITUTE($H7,",",REPT(" ",99)),298,99)))," ",""),SUBSTITUTE(SUBSTITUTE(SUBSTITUTE(UPPER(J7)," ",""),"SALES!",""),"CONTACTS!",""))),--ISNUMBER(FIND(SUBSTITUTE(UPPER(TRIM(MID(SUBSTITUTE($H7,",",REPT(" ",99)),298,99)))," ",""),SUBSTITUTE(SUBSTITUTE(SUBSTITUTE(SUBSTITUTE(UPPER(J7),"$","")," ",""),"SALES!",""),"CONTACTS!","")))))+IF(SUBSTITUTE(UPPER(TRIM(MID(SUBSTITUTE($H7,",",REPT(" ",99)),397,99)))," ","")="",0,IF(ISNUMBER(FIND("$",SUBSTITUTE(UPPER(TRIM(MID(SUBSTITUTE($H7,",",REPT(" ",99)),397,99)))," ",""))),--ISNUMBER(FIND(SUBSTITUTE(UPPER(TRIM(MID(SUBSTITUTE($H7,",",REPT(" ",99)),397,99)))," ",""),SUBSTITUTE(SUBSTITUTE(SUBSTITUTE(UPPER(J7)," ",""),"SALES!",""),"CONTACTS!",""))),--ISNUMBER(FIND(SUBSTITUTE(UPPER(TRIM(MID(SUBSTITUTE($H7,",",REPT(" ",99)),397,99)))," ",""),SUBSTITUTE(SUBSTITUTE(SUBSTITUTE(SUBSTITUTE(UPPER(J7),"$","")," ",""),"SALES!",""),"CONTACTS!","")))))+IF(SUBSTITUTE(UPPER(TRIM(MID(SUBSTITUTE($H7,",",REPT(" ",99)),496,99)))," ","")="",0,IF(ISNUMBER(FIND("$",SUBSTITUTE(UPPER(TRIM(MID(SUBSTITUTE($H7,",",REPT(" ",99)),496,99)))," ",""))),--ISNUMBER(FIND(SUBSTITUTE(UPPER(TRIM(MID(SUBSTITUTE($H7,",",REPT(" ",99)),496,99)))," ",""),SUBSTITUTE(SUBSTITUTE(SUBSTITUTE(UPPER(J7)," ",""),"SALES!",""),"CONTACTS!",""))),--ISNUMBER(FIND(SUBSTITUTE(UPPER(TRIM(MID(SUBSTITUTE($H7,",",REPT(" ",99)),496,99)))," ",""),SUBSTITUTE(SUBSTITUTE(SUBSTITUTE(SUBSTITUTE(UPPER(J7),"$","")," ",""),"SALES!",""),"CONTACTS!","")))))) | L7: =IF(SUBSTITUTE(UPPER(TRIM(MID(SUBSTITUTE($H7,",",REPT(" ",99)),1,99)))," ","")="",0,1)+IF(SUBSTITUTE(UPPER(TRIM(MID(SUBSTITUTE($H7,",",REPT(" ",99)),100,99)))," ","")="",0,1)+IF(SUBSTITUTE(UPPER(TRIM(MID(SUBSTITUTE($H7,",",REPT(" ",99)),199,99)))," ","")="",0,1)+IF(SUBSTITUTE(UPPER(TRIM(MID(SUBSTITUTE($H7,",",REPT(" ",99)),298,99)))," ","")="",0,1)+IF(SUBSTITUTE(UPPER(TRIM(MID(SUBSTITUTE($H7,",",REPT(" ",99)),397,99)))," ","")="",0,1)+IF(SUBSTITUTE(UPPER(TRIM(MID(SUBSTITUTE($H7,",",REPT(" ",99)),496,99)))," ","")="",0,1) | M7: =IF(J7="","",IF(AND(I7="formula",LEFT(TRIM(J7),1)<>"="),"FAIL",IF(K7=L7,"PASS","CHECK"))) | N7: dates are serial numbers; needs DATE() or a range test
A8: F07 | B8: Lookup | C8: Which region had the single highest revenue in one row? | D8: Sales!A1:F13 | E8: =LOKUP.V($C8, Sales!A1:F13) | F8: =INDEX(Sales!A2:A13,MATCH(MAX(Sales!F2:F13),Sales!F2:F13,0)) | G8: =INDEX(Sales!A2:A13,MATCH(MAX(Sales!F2:F13),Sales!F2:F13,0)) | H8: MAX,F2:F13,A2:A13 | I8: formula | K8: =IF(J8="","",IF(SUBSTITUTE(UPPER(TRIM(MID(SUBSTITUTE($H8,",",REPT(" ",99)),1,99)))," ","")="",0,IF(ISNUMBER(FIND("$",SUBSTITUTE(UPPER(TRIM(MID(SUBSTITUTE($H8,",",REPT(" ",99)),1,99)))," ",""))),--ISNUMBER(FIND(SUBSTITUTE(UPPER(TRIM(MID(SUBSTITUTE($H8,",",REPT(" ",99)),1,99)))," ",""),SUBSTITUTE(SUBSTITUTE(SUBSTITUTE(UPPER(J8)," ",""),"SALES!",""),"CONTACTS!",""))),--ISNUMBER(FIND(SUBSTITUTE(UPPER(TRIM(MID(SUBSTITUTE($H8,",",REPT(" ",99)),1,99)))," ",""),SUBSTITUTE(SUBSTITUTE(SUBSTITUTE(SUBSTITUTE(UPPER(J8),"$","")," ",""),"SALES!",""),"CONTACTS!","")))))+IF(SUBSTITUTE(UPPER(TRIM(MID(SUBSTITUTE($H8,",",REPT(" ",99)),100,99)))," ","")="",0,IF(ISNUMBER(FIND("$",SUBSTITUTE(UPPER(TRIM(MID(SUBSTITUTE($H8,",",REPT(" ",99)),100,99)))," ",""))),--ISNUMBER(FIND(SUBSTITUTE(UPPER(TRIM(MID(SUBSTITUTE($H8,",",REPT(" ",99)),100,99)))," ",""),SUBSTITUTE(SUBSTITUTE(SUBSTITUTE(UPPER(J8)," ",""),"SALES!",""),"CONTACTS!",""))),--ISNUMBER(FIND(SUBSTITUTE(UPPER(TRIM(MID(SUBSTITUTE($H8,",",REPT(" ",99)),100,99)))," ",""),SUBSTITUTE(SUBSTITUTE(SUBSTITUTE(SUBSTITUTE(UPPER(J8),"$","")," ",""),"SALES!",""),"CONTACTS!","")))))+IF(SUBSTITUTE(UPPER(TRIM(MID(SUBSTITUTE($H8,",",REPT(" ",99)),199,99)))," ","")="",0,IF(ISNUMBER(FIND("$",SUBSTITUTE(UPPER(TRIM(MID(SUBSTITUTE($H8,",",REPT(" ",99)),199,99)))," ",""))),--ISNUMBER(FIND(SUBSTITUTE(UPPER(TRIM(MID(SUBSTITUTE($H8,",",REPT(" ",99)),199,99)))," ",""),SUBSTITUTE(SUBSTITUTE(SUBSTITUTE(UPPER(J8)," ",""),"SALES!",""),"CONTACTS!",""))),--ISNUMBER(FIND(SUBSTITUTE(UPPER(TRIM(MID(SUBSTITUTE($H8,",",REPT(" ",99)),199,99)))," ",""),SUBSTITUTE(SUBSTITUTE(SUBSTITUTE(SUBSTITUTE(UPPER(J8),"$","")," ",""),"SALES!",""),"CONTACTS!","")))))+IF(SUBSTITUTE(UPPER(TRIM(MID(SUBSTITUTE($H8,",",REPT(" ",99)),298,99)))," ","")="",0,IF(ISNUMBER(FIND("$",SUBSTITUTE(UPPER(TRIM(MID(SUBSTITUTE($H8,",",REPT(" ",99)),298,99)))," ",""))),--ISNUMBER(FIND(SUBSTITUTE(UPPER(TRIM(MID(SUBSTITUTE($H8,",",REPT(" ",99)),298,99)))," ",""),SUBSTITUTE(SUBSTITUTE(SUBSTITUTE(UPPER(J8)," ",""),"SALES!",""),"CONTACTS!",""))),--ISNUMBER(FIND(SUBSTITUTE(UPPER(TRIM(MID(SUBSTITUTE($H8,",",REPT(" ",99)),298,99)))," ",""),SUBSTITUTE(SUBSTITUTE(SUBSTITUTE(SUBSTITUTE(UPPER(J8),"$","")," ",""),"SALES!",""),"CONTACTS!","")))))+IF(SUBSTITUTE(UPPER(TRIM(MID(SUBSTITUTE($H8,",",REPT(" ",99)),397,99)))," ","")="",0,IF(ISNUMBER(FIND("$",SUBSTITUTE(UPPER(TRIM(MID(SUBSTITUTE($H8,",",REPT(" ",99)),397,99)))," ",""))),--ISNUMBER(FIND(SUBSTITUTE(UPPER(TRIM(MID(SUBSTITUTE($H8,",",REPT(" ",99)),397,99)))," ",""),SUBSTITUTE(SUBSTITUTE(SUBSTITUTE(UPPER(J8)," ",""),"SALES!",""),"CONTACTS!",""))),--ISNUMBER(FIND(SUBSTITUTE(UPPER(TRIM(MID(SUBSTITUTE($H8,",",REPT(" ",99)),397,99)))," ",""),SUBSTITUTE(SUBSTITUTE(SUBSTITUTE(SUBSTITUTE(UPPER(J8),"$","")," ",""),"SALES!",""),"CONTACTS!","")))))+IF(SUBSTITUTE(UPPER(TRIM(MID(SUBSTITUTE($H8,",",REPT(" ",99)),496,99)))," ","")="",0,IF(ISNUMBER(FIND("$",SUBSTITUTE(UPPER(TRIM(MID(SUBSTITUTE($H8,",",REPT(" ",99)),496,99)))," ",""))),--ISNUMBER(FIND(SUBSTITUTE(UPPER(TRIM(MID(SUBSTITUTE($H8,",",REPT(" ",99)),496,99)))," ",""),SUBSTITUTE(SUBSTITUTE(SUBSTITUTE(UPPER(J8)," ",""),"SALES!",""),"CONTACTS!",""))),--ISNUMBER(FIND(SUBSTITUTE(UPPER(TRIM(MID(SUBSTITUTE($H8,",",REPT(" ",99)),496,99)))," ",""),SUBSTITUTE(SUBSTITUTE(SUBSTITUTE(SUBSTITUTE(UPPER(J8),"$","")," ",""),"SALES!",""),"CONTACTS!","")))))) | L8: =IF(SUBSTITUTE(UPPER(TRIM(MID(SUBSTITUTE($H8,",",REPT(" ",99)),1,99)))," ","")="",0,1)+IF(SUBSTITUTE(UPPER(TRIM(MID(SUBSTITUTE($H8,",",REPT(" ",99)),100,99)))," ","")="",0,1)+IF(SUBSTITUTE(UPPER(TRIM(MID(SUBSTITUTE($H8,",",REPT(" ",99)),199,99)))," ","")="",0,1)+IF(SUBSTITUTE(UPPER(TRIM(MID(SUBSTITUTE($H8,",",REPT(" ",99)),298,99)))," ","")="",0,1)+IF(SUBSTITUTE(UPPER(TRIM(MID(SUBSTITUTE($H8,",",REPT(" ",99)),397,99)))," ","")="",0,1)+IF(SUBSTITUTE(UPPER(TRIM(MID(SUBSTITUTE($H8,",",REPT(" ",99)),496,99)))," ","")="",0,1) | M8: =IF(J8="","",IF(AND(I8="formula",LEFT(TRIM(J8),1)<>"="),"FAIL",IF(K8=L8,"PASS","CHECK"))) | N8: INDEX/MATCH or XLOOKUP both pass
A9: F08 | B9: Row formula | C9: Revenue for row 2 from units and unit price. | D9: Sales!A1:F13 | E9: =LOKUP.V($C9, Sales!A1:F13) | F9: =Sales!D2*Sales!E2 | G9: =Sales!D2*Sales!E2 | H9: D2,E2,* | I9: formula | K9: =IF(J9="","",IF(SUBSTITUTE(UPPER(TRIM(MID(SUBSTITUTE($H9,",",REPT(" ",99)),1,99)))," ","")="",0,IF(ISNUMBER(FIND("$",SUBSTITUTE(UPPER(TRIM(MID(SUBSTITUTE($H9,",",REPT(" ",99)),1,99)))," ",""))),--ISNUMBER(FIND(SUBSTITUTE(UPPER(TRIM(MID(SUBSTITUTE($H9,",",REPT(" ",99)),1,99)))," ",""),SUBSTITUTE(SUBSTITUTE(SUBSTITUTE(UPPER(J9)," ",""),"SALES!",""),"CONTACTS!",""))),--ISNUMBER(FIND(SUBSTITUTE(UPPER(TRIM(MID(SUBSTITUTE($H9,",",REPT(" ",99)),1,99)))," ",""),SUBSTITUTE(SUBSTITUTE(SUBSTITUTE(SUBSTITUTE(UPPER(J9),"$","")," ",""),"SALES!",""),"CONTACTS!","")))))+IF(SUBSTITUTE(UPPER(TRIM(MID(SUBSTITUTE($H9,",",REPT(" ",99)),100,99)))," ","")="",0,IF(ISNUMBER(FIND("$",SUBSTITUTE(UPPER(TRIM(MID(SUBSTITUTE($H9,",",REPT(" ",99)),100,99)))," ",""))),--ISNUMBER(FIND(SUBSTITUTE(UPPER(TRIM(MID(SUBSTITUTE($H9,",",REPT(" ",99)),100,99)))," ",""),SUBSTITUTE(SUBSTITUTE(SUBSTITUTE(UPPER(J9)," ",""),"SALES!",""),"CONTACTS!",""))),--ISNUMBER(FIND(SUBSTITUTE(UPPER(TRIM(MID(SUBSTITUTE($H9,",",REPT(" ",99)),100,99)))," ",""),SUBSTITUTE(SUBSTITUTE(SUBSTITUTE(SUBSTITUTE(UPPER(J9),"$","")," ",""),"SALES!",""),"CONTACTS!","")))))+IF(SUBSTITUTE(UPPER(TRIM(MID(SUBSTITUTE($H9,",",REPT(" ",99)),199,99)))," ","")="",0,IF(ISNUMBER(FIND("$",SUBSTITUTE(UPPER(TRIM(MID(SUBSTITUTE($H9,",",REPT(" ",99)),199,99)))," ",""))),--ISNUMBER(FIND(SUBSTITUTE(UPPER(TRIM(MID(SUBSTITUTE($H9,",",REPT(" ",99)),199,99)))," ",""),SUBSTITUTE(SUBSTITUTE(SUBSTITUTE(UPPER(J9)," ",""),"SALES!",""),"CONTACTS!",""))),--ISNUMBER(FIND(SUBSTITUTE(UPPER(TRIM(MID(SUBSTITUTE($H9,",",REPT(" ",99)),199,99)))," ",""),SUBSTITUTE(SUBSTITUTE(SUBSTITUTE(SUBSTITUTE(UPPER(J9),"$","")," ",""),"SALES!",""),"CONTACTS!","")))))+IF(SUBSTITUTE(UPPER(TRIM(MID(SUBSTITUTE($H9,",",REPT(" ",99)),298,99)))," ","")="",0,IF(ISNUMBER(FIND("$",SUBSTITUTE(UPPER(TRIM(MID(SUBSTITUTE($H9,",",REPT(" ",99)),298,99)))," ",""))),--ISNUMBER(FIND(SUBSTITUTE(UPPER(TRIM(MID(SUBSTITUTE($H9,",",REPT(" ",99)),298,99)))," ",""),SUBSTITUTE(SUBSTITUTE(SUBSTITUTE(UPPER(J9)," ",""),"SALES!",""),"CONTACTS!",""))),--ISNUMBER(FIND(SUBSTITUTE(UPPER(TRIM(MID(SUBSTITUTE($H9,",",REPT(" ",99)),298,99)))," ",""),SUBSTITUTE(SUBSTITUTE(SUBSTITUTE(SUBSTITUTE(UPPER(J9),"$","")," ",""),"SALES!",""),"CONTACTS!","")))))+IF(SUBSTITUTE(UPPER(TRIM(MID(SUBSTITUTE($H9,",",REPT(" ",99)),397,99)))," ","")="",0,IF(ISNUMBER(FIND("$",SUBSTITUTE(UPPER(TRIM(MID(SUBSTITUTE($H9,",",REPT(" ",99)),397,99)))," ",""))),--ISNUMBER(FIND(SUBSTITUTE(UPPER(TRIM(MID(SUBSTITUTE($H9,",",REPT(" ",99)),397,99)))," ",""),SUBSTITUTE(SUBSTITUTE(SUBSTITUTE(UPPER(J9)," ",""),"SALES!",""),"CONTACTS!",""))),--ISNUMBER(FIND(SUBSTITUTE(UPPER(TRIM(MID(SUBSTITUTE($H9,",",REPT(" ",99)),397,99)))," ",""),SUBSTITUTE(SUBSTITUTE(SUBSTITUTE(SUBSTITUTE(UPPER(J9),"$","")," ",""),"SALES!",""),"CONTACTS!","")))))+IF(SUBSTITUTE(UPPER(TRIM(MID(SUBSTITUTE($H9,",",REPT(" ",99)),496,99)))," ","")="",0,IF(ISNUMBER(FIND("$",SUBSTITUTE(UPPER(TRIM(MID(SUBSTITUTE($H9,",",REPT(" ",99)),496,99)))," ",""))),--ISNUMBER(FIND(SUBSTITUTE(UPPER(TRIM(MID(SUBSTITUTE($H9,",",REPT(" ",99)),496,99)))," ",""),SUBSTITUTE(SUBSTITUTE(SUBSTITUTE(UPPER(J9)," ",""),"SALES!",""),"CONTACTS!",""))),--ISNUMBER(FIND(SUBSTITUTE(UPPER(TRIM(MID(SUBSTITUTE($H9,",",REPT(" ",99)),496,99)))," ",""),SUBSTITUTE(SUBSTITUTE(SUBSTITUTE(SUBSTITUTE(UPPER(J9),"$","")," ",""),"SALES!",""),"CONTACTS!","")))))) | L9: =IF(SUBSTITUTE(UPPER(TRIM(MID(SUBSTITUTE($H9,",",REPT(" ",99)),1,99)))," ","")="",0,1)+IF(SUBSTITUTE(UPPER(TRIM(MID(SUBSTITUTE($H9,",",REPT(" ",99)),100,99)))," ","")="",0,1)+IF(SUBSTITUTE(UPPER(TRIM(MID(SUBSTITUTE($H9,",",REPT(" ",99)),199,99)))," ","")="",0,1)+IF(SUBSTITUTE(UPPER(TRIM(MID(SUBSTITUTE($H9,",",REPT(" ",99)),298,99)))," ","")="",0,1)+IF(SUBSTITUTE(UPPER(TRIM(MID(SUBSTITUTE($H9,",",REPT(" ",99)),397,99)))," ","")="",0,1)+IF(SUBSTITUTE(UPPER(TRIM(MID(SUBSTITUTE($H9,",",REPT(" ",99)),496,99)))," ","")="",0,1) | M9: =IF(J9="","",IF(AND(I9="formula",LEFT(TRIM(J9),1)<>"="),"FAIL",IF(K9=L9,"PASS","CHECK"))) | N9: picks the right two columns
A10: F09 | B10: Row formula | C10: Revenue in row 2 with 18% GST added. | D10: Sales!A1:F13 | E10: =LOKUP.V($C10, Sales!A1:F13) | F10: =Sales!F2*1.18 | G10: =Sales!F2*1.18 | H10: F2,18 | I10: formula | K10: =IF(J10="","",IF(SUBSTITUTE(UPPER(TRIM(MID(SUBSTITUTE($H10,",",REPT(" ",99)),1,99)))," ","")="",0,IF(ISNUMBER(FIND("$",SUBSTITUTE(UPPER(TRIM(MID(SUBSTITUTE($H10,",",REPT(" ",99)),1,99)))," ",""))),--ISNUMBER(FIND(SUBSTITUTE(UPPER(TRIM(MID(SUBSTITUTE($H10,",",REPT(" ",99)),1,99)))," ",""),SUBSTITUTE(SUBSTITUTE(SUBSTITUTE(UPPER(J10)," ",""),"SALES!",""),"CONTACTS!",""))),--ISNUMBER(FIND(SUBSTITUTE(UPPER(TRIM(MID(SUBSTITUTE($H10,",",REPT(" ",99)),1,99)))," ",""),SUBSTITUTE(SUBSTITUTE(SUBSTITUTE(SUBSTITUTE(UPPER(J10),"$","")," ",""),"SALES!",""),"CONTACTS!","")))))+IF(SUBSTITUTE(UPPER(TRIM(MID(SUBSTITUTE($H10,",",REPT(" ",99)),100,99)))," ","")="",0,IF(ISNUMBER(FIND("$",SUBSTITUTE(UPPER(TRIM(MID(SUBSTITUTE($H10,",",REPT(" ",99)),100,99)))," ",""))),--ISNUMBER(FIND(SUBSTITUTE(UPPER(TRIM(MID(SUBSTITUTE($H10,",",REPT(" ",99)),100,99)))," ",""),SUBSTITUTE(SUBSTITUTE(SUBSTITUTE(UPPER(J10)," ",""),"SALES!",""),"CONTACTS!",""))),--ISNUMBER(FIND(SUBSTITUTE(UPPER(TRIM(MID(SUBSTITUTE($H10,",",REPT(" ",99)),100,99)))," ",""),SUBSTITUTE(SUBSTITUTE(SUBSTITUTE(SUBSTITUTE(UPPER(J10),"$","")," ",""),"SALES!",""),"CONTACTS!","")))))+IF(SUBSTITUTE(UPPER(TRIM(MID(SUBSTITUTE($H10,",",REPT(" ",99)),199,99)))," ","")="",0,IF(ISNUMBER(FIND("$",SUBSTITUTE(UPPER(TRIM(MID(SUBSTITUTE($H10,",",REPT(" ",99)),199,99)))," ",""))),--ISNUMBER(FIND(SUBSTITUTE(UPPER(TRIM(MID(SUBSTITUTE($H10,",",REPT(" ",99)),199,99)))," ",""),SUBSTITUTE(SUBSTITUTE(SUBSTITUTE(UPPER(J10)," ",""),"SALES!",""),"CONTACTS!",""))),--ISNUMBER(FIND(SUBSTITUTE(UPPER(TRIM(MID(SUBSTITUTE($H10,",",REPT(" ",99)),199,99)))," ",""),SUBSTITUTE(SUBSTITUTE(SUBSTITUTE(SUBSTITUTE(UPPER(J10),"$","")," ",""),"SALES!",""),"CONTACTS!","")))))+IF(SUBSTITUTE(UPPER(TRIM(MID(SUBSTITUTE($H10,",",REPT(" ",99)),298,99)))," ","")="",0,IF(ISNUMBER(FIND("$",SUBSTITUTE(UPPER(TRIM(MID(SUBSTITUTE($H10,",",REPT(" ",99)),298,99)))," ",""))),--ISNUMBER(FIND(SUBSTITUTE(UPPER(TRIM(MID(SUBSTITUTE($H10,",",REPT(" ",99)),298,99)))," ",""),SUBSTITUTE(SUBSTITUTE(SUBSTITUTE(UPPER(J10)," ",""),"SALES!",""),"CONTACTS!",""))),--ISNUMBER(FIND(SUBSTITUTE(UPPER(TRIM(MID(SUBSTITUTE($H10,",",REPT(" ",99)),298,99)))," ",""),SUBSTITUTE(SUBSTITUTE(SUBSTITUTE(SUBSTITUTE(UPPER(J10),"$","")," ",""),"SALES!",""),"CONTACTS!","")))))+IF(SUBSTITUTE(UPPER(TRIM(MID(SUBSTITUTE($H10,",",REPT(" ",99)),397,99)))," ","")="",0,IF(ISNUMBER(FIND("$",SUBSTITUTE(UPPER(TRIM(MID(SUBSTITUTE($H10,",",REPT(" ",99)),397,99)))," ",""))),--ISNUMBER(FIND(SUBSTITUTE(UPPER(TRIM(MID(SUBSTITUTE($H10,",",REPT(" ",99)),397,99)))," ",""),SUBSTITUTE(SUBSTITUTE(SUBSTITUTE(UPPER(J10)," ",""),"SALES!",""),"CONTACTS!",""))),--ISNUMBER(FIND(SUBSTITUTE(UPPER(TRIM(MID(SUBSTITUTE($H10,",",REPT(" ",99)),397,99)))," ",""),SUBSTITUTE(SUBSTITUTE(SUBSTITUTE(SUBSTITUTE(UPPER(J10),"$","")," ",""),"SALES!",""),"CONTACTS!","")))))+IF(SUBSTITUTE(UPPER(TRIM(MID(SUBSTITUTE($H10,",",REPT(" ",99)),496,99)))," ","")="",0,IF(ISNUMBER(FIND("$",SUBSTITUTE(UPPER(TRIM(MID(SUBSTITUTE($H10,",",REPT(" ",99)),496,99)))," ",""))),--ISNUMBER(FIND(SUBSTITUTE(UPPER(TRIM(MID(SUBSTITUTE($H10,",",REPT(" ",99)),496,99)))," ",""),SUBSTITUTE(SUBSTITUTE(SUBSTITUTE(UPPER(J10)," ",""),"SALES!",""),"CONTACTS!",""))),--ISNUMBER(FIND(SUBSTITUTE(UPPER(TRIM(MID(SUBSTITUTE($H10,",",REPT(" ",99)),496,99)))," ",""),SUBSTITUTE(SUBSTITUTE(SUBSTITUTE(SUBSTITUTE(UPPER(J10),"$","")," ",""),"SALES!",""),"CONTACTS!","")))))) | L10: =IF(SUBSTITUTE(UPPER(TRIM(MID(SUBSTITUTE($H10,",",REPT(" ",99)),1,99)))," ","")="",0,1)+IF(SUBSTITUTE(UPPER(TRIM(MID(SUBSTITUTE($H10,",",REPT(" ",99)),100,99)))," ","")="",0,1)+IF(SUBSTITUTE(UPPER(TRIM(MID(SUBSTITUTE($H10,",",REPT(" ",99)),199,99)))," ","")="",0,1)+IF(SUBSTITUTE(UPPER(TRIM(MID(SUBSTITUTE($H10,",",REPT(" ",99)),298,99)))," ","")="",0,1)+IF(SUBSTITUTE(UPPER(TRIM(MID(SUBSTITUTE($H10,",",REPT(" ",99)),397,99)))," ","")="",0,1)+IF(SUBSTITUTE(UPPER(TRIM(MID(SUBSTITUTE($H10,",",REPT(" ",99)),496,99)))," ","")="",0,1) | M10: =IF(J10="","",IF(AND(I10="formula",LEFT(TRIM(J10),1)<>"="),"FAIL",IF(K10=L10,"PASS","CHECK"))) | N10: F2*1.18, F2*(1+18%), F2+F2*0.18 all pass
A11: F10 | B11: Logic | C11: Show High if units in row 3 are 100 or more, otherwise Low. | D11: Sales!A1:F13 | E11: =LOKUP.V($C11, Sales!A1:F13) | F11: =IF(Sales!D3>=100,"High","Low") | G11: =IF(Sales!D3>=100,"High","Low") | H11: IF(,D3,100,HIGH,LOW | I11: formula | K11: =IF(J11="","",IF(SUBSTITUTE(UPPER(TRIM(MID(SUBSTITUTE($H11,",",REPT(" ",99)),1,99)))," ","")="",0,IF(ISNUMBER(FIND("$",SUBSTITUTE(UPPER(TRIM(MID(SUBSTITUTE($H11,",",REPT(" ",99)),1,99)))," ",""))),--ISNUMBER(FIND(SUBSTITUTE(UPPER(TRIM(MID(SUBSTITUTE($H11,",",REPT(" ",99)),1,99)))," ",""),SUBSTITUTE(SUBSTITUTE(SUBSTITUTE(UPPER(J11)," ",""),"SALES!",""),"CONTACTS!",""))),--ISNUMBER(FIND(SUBSTITUTE(UPPER(TRIM(MID(SUBSTITUTE($H11,",",REPT(" ",99)),1,99)))," ",""),SUBSTITUTE(SUBSTITUTE(SUBSTITUTE(SUBSTITUTE(UPPER(J11),"$","")," ",""),"SALES!",""),"CONTACTS!","")))))+IF(SUBSTITUTE(UPPER(TRIM(MID(SUBSTITUTE($H11,",",REPT(" ",99)),100,99)))," ","")="",0,IF(ISNUMBER(FIND("$",SUBSTITUTE(UPPER(TRIM(MID(SUBSTITUTE($H11,",",REPT(" ",99)),100,99)))," ",""))),--ISNUMBER(FIND(SUBSTITUTE(UPPER(TRIM(MID(SUBSTITUTE($H11,",",REPT(" ",99)),100,99)))," ",""),SUBSTITUTE(SUBSTITUTE(SUBSTITUTE(UPPER(J11)," ",""),"SALES!",""),"CONTACTS!",""))),--ISNUMBER(FIND(SUBSTITUTE(UPPER(TRIM(MID(SUBSTITUTE($H11,",",REPT(" ",99)),100,99)))," ",""),SUBSTITUTE(SUBSTITUTE(SUBSTITUTE(SUBSTITUTE(UPPER(J11),"$","")," ",""),"SALES!",""),"CONTACTS!","")))))+IF(SUBSTITUTE(UPPER(TRIM(MID(SUBSTITUTE($H11,",",REPT(" ",99)),199,99)))," ","")="",0,IF(ISNUMBER(FIND("$",SUBSTITUTE(UPPER(TRIM(MID(SUBSTITUTE($H11,",",REPT(" ",99)),199,99)))," ",""))),--ISNUMBER(FIND(SUBSTITUTE(UPPER(TRIM(MID(SUBSTITUTE($H11,",",REPT(" ",99)),199,99)))," ",""),SUBSTITUTE(SUBSTITUTE(SUBSTITUTE(UPPER(J11)," ",""),"SALES!",""),"CONTACTS!",""))),--ISNUMBER(FIND(SUBSTITUTE(UPPER(TRIM(MID(SUBSTITUTE($H11,",",REPT(" ",99)),199,99)))," ",""),SUBSTITUTE(SUBSTITUTE(SUBSTITUTE(SUBSTITUTE(UPPER(J11),"$","")," ",""),"SALES!",""),"CONTACTS!","")))))+IF(SUBSTITUTE(UPPER(TRIM(MID(SUBSTITUTE($H11,",",REPT(" ",99)),298,99)))," ","")="",0,IF(ISNUMBER(FIND("$",SUBSTITUTE(UPPER(TRIM(MID(SUBSTITUTE($H11,",",REPT(" ",99)),298,99)))," ",""))),--ISNUMBER(FIND(SUBSTITUTE(UPPER(TRIM(MID(SUBSTITUTE($H11,",",REPT(" ",99)),298,99)))," ",""),SUBSTITUTE(SUBSTITUTE(SUBSTITUTE(UPPER(J11)," ",""),"SALES!",""),"CONTACTS!",""))),--ISNUMBER(FIND(SUBSTITUTE(UPPER(TRIM(MID(SUBSTITUTE($H11,",",REPT(" ",99)),298,99)))," ",""),SUBSTITUTE(SUBSTITUTE(SUBSTITUTE(SUBSTITUTE(UPPER(J11),"$","")," ",""),"SALES!",""),"CONTACTS!","")))))+IF(SUBSTITUTE(UPPER(TRIM(MID(SUBSTITUTE($H11,",",REPT(" ",99)),397,99)))," ","")="",0,IF(ISNUMBER(FIND("$",SUBSTITUTE(UPPER(TRIM(MID(SUBSTITUTE($H11,",",REPT(" ",99)),397,99)))," ",""))),--ISNUMBER(FIND(SUBSTITUTE(UPPER(TRIM(MID(SUBSTITUTE($H11,",",REPT(" ",99)),397,99)))," ",""),SUBSTITUTE(SUBSTITUTE(SUBSTITUTE(UPPER(J11)," ",""),"SALES!",""),"CONTACTS!",""))),--ISNUMBER(FIND(SUBSTITUTE(UPPER(TRIM(MID(SUBSTITUTE($H11,",",REPT(" ",99)),397,99)))," ",""),SUBSTITUTE(SUBSTITUTE(SUBSTITUTE(SUBSTITUTE(UPPER(J11),"$","")," ",""),"SALES!",""),"CONTACTS!","")))))+IF(SUBSTITUTE(UPPER(TRIM(MID(SUBSTITUTE($H11,",",REPT(" ",99)),496,99)))," ","")="",0,IF(ISNUMBER(FIND("$",SUBSTITUTE(UPPER(TRIM(MID(SUBSTITUTE($H11,",",REPT(" ",99)),496,99)))," ",""))),--ISNUMBER(FIND(SUBSTITUTE(UPPER(TRIM(MID(SUBSTITUTE($H11,",",REPT(" ",99)),496,99)))," ",""),SUBSTITUTE(SUBSTITUTE(SUBSTITUTE(UPPER(J11)," ",""),"SALES!",""),"CONTACTS!",""))),--ISNUMBER(FIND(SUBSTITUTE(UPPER(TRIM(MID(SUBSTITUTE($H11,",",REPT(" ",99)),496,99)))," ",""),SUBSTITUTE(SUBSTITUTE(SUBSTITUTE(SUBSTITUTE(UPPER(J11),"$","")," ",""),"SALES!",""),"CONTACTS!","")))))) | L11: =IF(SUBSTITUTE(UPPER(TRIM(MID(SUBSTITUTE($H11,",",REPT(" ",99)),1,99)))," ","")="",0,1)+IF(SUBSTITUTE(UPPER(TRIM(MID(SUBSTITUTE($H11,",",REPT(" ",99)),100,99)))," ","")="",0,1)+IF(SUBSTITUTE(UPPER(TRIM(MID(SUBSTITUTE($H11,",",REPT(" ",99)),199,99)))," ","")="",0,1)+IF(SUBSTITUTE(UPPER(TRIM(MID(SUBSTITUTE($H11,",",REPT(" ",99)),298,99)))," ","")="",0,1)+IF(SUBSTITUTE(UPPER(TRIM(MID(SUBSTITUTE($H11,",",REPT(" ",99)),397,99)))," ","")="",0,1)+IF(SUBSTITUTE(UPPER(TRIM(MID(SUBSTITUTE($H11,",",REPT(" ",99)),496,99)))," ","")="",0,1) | M11: =IF(J11="","",IF(AND(I11="formula",LEFT(TRIM(J11),1)<>"="),"FAIL",IF(K11=L11,"PASS","CHECK"))) | N11: row 3: units 80 but revenue 32,000, so using the wrong column gives the wrong label
A12: F11 | B12: Absolute refs | C12: Row 2's share of total revenue, as a formula I can drag down to row 13. | D12: Sales!A1:F13 | E12: =LOKUP.V($C12, Sales!A1:F13) | F12: =Sales!F2/SUM(Sales!$F$2:$F$13) | G12: =Sales!F2/SUM(Sales!$F$2:$F$13) | H12: F2/,$F$2:$F$13 | I12: formula | K12: =IF(J12="","",IF(SUBSTITUTE(UPPER(TRIM(MID(SUBSTITUTE($H12,",",REPT(" ",99)),1,99)))," ","")="",0,IF(ISNUMBER(FIND("$",SUBSTITUTE(UPPER(TRIM(MID(SUBSTITUTE($H12,",",REPT(" ",99)),1,99)))," ",""))),--ISNUMBER(FIND(SUBSTITUTE(UPPER(TRIM(MID(SUBSTITUTE($H12,",",REPT(" ",99)),1,99)))," ",""),SUBSTITUTE(SUBSTITUTE(SUBSTITUTE(UPPER(J12)," ",""),"SALES!",""),"CONTACTS!",""))),--ISNUMBER(FIND(SUBSTITUTE(UPPER(TRIM(MID(SUBSTITUTE($H12,",",REPT(" ",99)),1,99)))," ",""),SUBSTITUTE(SUBSTITUTE(SUBSTITUTE(SUBSTITUTE(UPPER(J12),"$","")," ",""),"SALES!",""),"CONTACTS!","")))))+IF(SUBSTITUTE(UPPER(TRIM(MID(SUBSTITUTE($H12,",",REPT(" ",99)),100,99)))," ","")="",0,IF(ISNUMBER(FIND("$",SUBSTITUTE(UPPER(TRIM(MID(SUBSTITUTE($H12,",",REPT(" ",99)),100,99)))," ",""))),--ISNUMBER(FIND(SUBSTITUTE(UPPER(TRIM(MID(SUBSTITUTE($H12,",",REPT(" ",99)),100,99)))," ",""),SUBSTITUTE(SUBSTITUTE(SUBSTITUTE(UPPER(J12)," ",""),"SALES!",""),"CONTACTS!",""))),--ISNUMBER(FIND(SUBSTITUTE(UPPER(TRIM(MID(SUBSTITUTE($H12,",",REPT(" ",99)),100,99)))," ",""),SUBSTITUTE(SUBSTITUTE(SUBSTITUTE(SUBSTITUTE(UPPER(J12),"$","")," ",""),"SALES!",""),"CONTACTS!","")))))+IF(SUBSTITUTE(UPPER(TRIM(MID(SUBSTITUTE($H12,",",REPT(" ",99)),199,99)))," ","")="",0,IF(ISNUMBER(FIND("$",SUBSTITUTE(UPPER(TRIM(MID(SUBSTITUTE($H12,",",REPT(" ",99)),199,99)))," ",""))),--ISNUMBER(FIND(SUBSTITUTE(UPPER(TRIM(MID(SUBSTITUTE($H12,",",REPT(" ",99)),199,99)))," ",""),SUBSTITUTE(SUBSTITUTE(SUBSTITUTE(UPPER(J12)," ",""),"SALES!",""),"CONTACTS!",""))),--ISNUMBER(FIND(SUBSTITUTE(UPPER(TRIM(MID(SUBSTITUTE($H12,",",REPT(" ",99)),199,99)))," ",""),SUBSTITUTE(SUBSTITUTE(SUBSTITUTE(SUBSTITUTE(UPPER(J12),"$","")," ",""),"SALES!",""),"CONTACTS!","")))))+IF(SUBSTITUTE(UPPER(TRIM(MID(SUBSTITUTE($H12,",",REPT(" ",99)),298,99)))," ","")="",0,IF(ISNUMBER(FIND("$",SUBSTITUTE(UPPER(TRIM(MID(SUBSTITUTE($H12,",",REPT(" ",99)),298,99)))," ",""))),--ISNUMBER(FIND(SUBSTITUTE(UPPER(TRIM(MID(SUBSTITUTE($H12,",",REPT(" ",99)),298,99)))," ",""),SUBSTITUTE(SUBSTITUTE(SUBSTITUTE(UPPER(J12)," ",""),"SALES!",""),"CONTACTS!",""))),--ISNUMBER(FIND(SUBSTITUTE(UPPER(TRIM(MID(SUBSTITUTE($H12,",",REPT(" ",99)),298,99)))," ",""),SUBSTITUTE(SUBSTITUTE(SUBSTITUTE(SUBSTITUTE(UPPER(J12),"$","")," ",""),"SALES!",""),"CONTACTS!","")))))+IF(SUBSTITUTE(UPPER(TRIM(MID(SUBSTITUTE($H12,",",REPT(" ",99)),397,99)))," ","")="",0,IF(ISNUMBER(FIND("$",SUBSTITUTE(UPPER(TRIM(MID(SUBSTITUTE($H12,",",REPT(" ",99)),397,99)))," ",""))),--ISNUMBER(FIND(SUBSTITUTE(UPPER(TRIM(MID(SUBSTITUTE($H12,",",REPT(" ",99)),397,99)))," ",""),SUBSTITUTE(SUBSTITUTE(SUBSTITUTE(UPPER(J12)," ",""),"SALES!",""),"CONTACTS!",""))),--ISNUMBER(FIND(SUBSTITUTE(UPPER(TRIM(MID(SUBSTITUTE($H12,",",REPT(" ",99)),397,99)))," ",""),SUBSTITUTE(SUBSTITUTE(SUBSTITUTE(SUBSTITUTE(UPPER(J12),"$","")," ",""),"SALES!",""),"CONTACTS!","")))))+IF(SUBSTITUTE(UPPER(TRIM(MID(SUBSTITUTE($H12,",",REPT(" ",99)),496,99)))," ","")="",0,IF(ISNUMBER(FIND("$",SUBSTITUTE(UPPER(TRIM(MID(SUBSTITUTE($H12,",",REPT(" ",99)),496,99)))," ",""))),--ISNUMBER(FIND(SUBSTITUTE(UPPER(TRIM(MID(SUBSTITUTE($H12,",",REPT(" ",99)),496,99)))," ",""),SUBSTITUTE(SUBSTITUTE(SUBSTITUTE(UPPER(J12)," ",""),"SALES!",""),"CONTACTS!",""))),--ISNUMBER(FIND(SUBSTITUTE(UPPER(TRIM(MID(SUBSTITUTE($H12,",",REPT(" ",99)),496,99)))," ",""),SUBSTITUTE(SUBSTITUTE(SUBSTITUTE(SUBSTITUTE(UPPER(J12),"$","")," ",""),"SALES!",""),"CONTACTS!","")))))) | L12: =IF(SUBSTITUTE(UPPER(TRIM(MID(SUBSTITUTE($H12,",",REPT(" ",99)),1,99)))," ","")="",0,1)+IF(SUBSTITUTE(UPPER(TRIM(MID(SUBSTITUTE($H12,",",REPT(" ",99)),100,99)))," ","")="",0,1)+IF(SUBSTITUTE(UPPER(TRIM(MID(SUBSTITUTE($H12,",",REPT(" ",99)),199,99)))," ","")="",0,1)+IF(SUBSTITUTE(UPPER(TRIM(MID(SUBSTITUTE($H12,",",REPT(" ",99)),298,99)))," ","")="",0,1)+IF(SUBSTITUTE(UPPER(TRIM(MID(SUBSTITUTE($H12,",",REPT(" ",99)),397,99)))," ","")="",0,1)+IF(SUBSTITUTE(UPPER(TRIM(MID(SUBSTITUTE($H12,",",REPT(" ",99)),496,99)))," ","")="",0,1) | M12: =IF(J12="","",IF(AND(I12="formula",LEFT(TRIM(J12),1)<>"="),"FAIL",IF(K12=L12,"PASS","CHECK"))) | N12: must lock the total range with $
