Workbook

Sheet Read Me
A1: DATA ANALYTICS | EXCEL ASSESSMENT
A2: Mock analyst recruitment exercise • E-commerce performance & data quality • 60 minutes
A4: Candidate brief
A5: Scenario | B5: You are a Data Analyst supporting an e-commerce business. The manager wants a reliable performance snapshot for July–September 2026 and a short list of actionable insights.
A6: Time limit | B6: 60 minutes. Work in Excel only. Do not use external sources. Use formulas, PivotTables, filters or other standard Excel features where appropriate.
A7: Data notes | B7: The 'Raw Data' tab contains synthetic order-level records. Some records include missing fields, a duplicate order ID, and orders with different statuses. Do not silently delete data without explaining your treatment.
A8: Task 1 — Data quality (10 min) | B8: On 'Analysis', identify duplicate Order IDs, missing Customer ID / Region / Discount values, and create a clean status or data-quality flag. State how you would treat each issue.
A9: Task 2 — Create metrics (15 min) | B9: Add formulas on 'Raw Data' for Gross Sales (Unit Price × Quantity), Net Sales after discount, Gross Profit (Net Sales − Cost), and a Delivered flag. Handle missing discount values sensibly and document your assumption.
A10: Task 3 — Business analysis (20 min) | B10: On 'Analysis', calculate total orders, delivered orders, cancellation rate, return rate, net sales, gross profit, gross margin, average order value (AOV), and net sales by region, channel and category. Define denominators clearly; avoid treating cancelled/returned orders as delivered sales.
A11: Task 4 — Insights (10 min) | B11: Identify the best-performing region, channel and category using a clearly stated metric. Provide two actionable insights and one caveat about data quality or interpretation.
A12: Task 5 — Presentation (5 min) | B12: Create a compact summary table and at least one chart or PivotTable. Keep formulas readable, apply appropriate number formats and make your assumptions explicit.
A13: Formatting | B13: Blue font for raw inputs, black font for formulas, currency in INR, percentages as 0.0%, counts as whole numbers. Avoid hardcoding derived metrics.
A14: Important | B14: This is a realistic practice simulation, not a claim that every employer uses this exact test. Data analytics Excel rounds may focus on cleaning, lookups, PivotTables, formulas, dashboards, or business interpretation.

Sheet Raw Data
A1: RAW ORDER DATA
A2: Synthetic e-commerce transactions. Derived columns at right are intentionally blank for the candidate to calculate.
A4: Order ID | B4: Order Date | C4: Customer ID | D4: Region | E4: Channel | F4: Category | G4: Product | H4: Quantity | I4: Unit Price (INR) | J4: Discount % | K4: Cost (INR) | L4: Reported Revenue (INR) | M4: Status | N4: Rating | O4: Gross Sales (INR) | P4: Net Sales (INR) | Q4: Gross Profit (INR) | R4: Delivered Flag
A5: ORD5001 | B5: 46204 | C5: C1026 | D5: East | E5: Website | F5: Home & Kitchen | G5: Bedsheet Set | H5: 1 | I5: 1528.98 | J5: 0.2 | K5: 743.71 | L5: 1223.18 | M5: Delivered | N5: 2 | O5: =I5*H5 | P5: =O5*(1-IF(J5="",0,J5)) | Q5: =P5-K5 | R5: =IF(M5="Delivered",1,0)
A6: ORD5002 | B6: 46205 | C6: C1030 | D6: East | E6: Website | F6: Sports | G6: Dumbbell Set | H6: 2 | I6: 2424.03 | J6: 0.1 | K6: 3097.17 | L6: 4363.25 | M6: Delivered | N6: 5 | O6: =I6*H6 | P6: =O6*(1-IF(J6="",0,J6)) | Q6: =P6-K6 | R6: =IF(M6="Delivered",1,0)
A7: ORD5003 | B7: 46206 | C7: C1022 | D7: West | E7: Website | F7: Electronics | G7: Smart Watch | H7: 1 | I7: 4078.98 | J7: 0.15 | K7: 2919.7 | L7: 3467.13 | M7: Delivered | N7: 1 | O7: =I7*H7 | P7: =O7*(1-IF(J7="",0,J7)) | Q7: =P7-K7 | R7: =IF(M7="Delivered",1,0)
A8: ORD5004 | B8: 46207 | C8: C1020 | D8: Central | E8: Website | F8: Fashion | G8: Backpack | H8: 3 | I8: 1899 | J8: 0.05 | K8: 3247.61 | L8: 5412.15 | M8: Delivered | N8: 3 | O8: =I8*H8 | P8: =O8*(1-IF(J8="",0,J8)) | Q8: =P8-K8 | R8: =IF(M8="Delivered",1,0)
A9: ORD5005 | B9: 46208 | C9: C1059 | D9: North | E9: Website | F9: Home & Kitchen | G9: Mixer Grinder | H9: 3 | I9: 3299 | J9: 0.05 | K9: 5018.03 | L9: 9402.15 | M9: Delivered | N9: 3 | O9: =I9*H9 | P9: =O9*(1-IF(J9="",0,J9)) | Q9: =P9-K9 | R9: =IF(M9="Delivered",1,0)
A10: ORD5006 | B10: 46209 | C10: C1044 | D10: Central | E10: Mobile App | F10: Home & Kitchen | G10: Bedsheet Set | H10: 3 | I10: 1499 | J10: 0 | K10: 2170.28 | L10: 4497 | M10: Delivered | N10: 1 | O10: =I10*H10 | P10: =O10*(1-IF(J10="",0,J10)) | Q10: =P10-K10 | R10: =IF(M10="Delivered",1,0)
A11: ORD5007 | B11: 46210 | C11: C1055 | D11: South | E11: Website | F11: Fashion | G11: Running Shoes | H11: 1 | I11: 2938.95 | J11: 0.15 | K11: 1831.63 | L11: 2498.11 | M11: Delivered | N11: 2 | O11: =I11*H11 | P11: =O11*(1-IF(J11="",0,J11)) | Q11: =P11-K11 | R11: =IF(M11="Delivered",1,0)
A12: ORD5008 | B12: 46211 | C12: C1008 | D12: East | E12: Website | F12: Beauty | G12: Hair Dryer | H12: 1 | I12: 2308.95 | J12: 0.2 | K12: 1121.78 | L12: 1847.16 | M12: Delivered | N12: 5 | O12: =I12*H12 | P12: =O12*(1-IF(J12="",0,J12)) | Q12: =P12-K12 | R12: =IF(M12="Delivered",1,0)
A13: ORD5009 | B13: 46212 | C13: C1060 | D13: West | E13: Mobile App | F13: Home & Kitchen | G13: Mixer Grinder | H13: 1 | I13: 3299 | J13: 0.2 | K13: 2181.8 | L13: 2639.2 | M13: Delivered | N13: 2 | O13: =I13*H13 | P13: =O13*(1-IF(J13="",0,J13)) | Q13: =P13-K13 | R13: =IF(M13="Delivered",1,0)
A14: ORD5010 | B14: 46213 | C14: C1051 | D14: East | E14: Mobile App | F14: Sports | G14: Cricket Kit | H14: 1 | I14: 3568.98 | J14: 0.05 | K14: 2161.02 | L14: 3390.53 | M14: Delivered | N14: 5 | O14: =I14*H14 | P14: =O14*(1-IF(J14="",0,J14)) | Q14: =P14-K14 | R14: =IF(M14="Delivered",1,0)
A15: ORD5011 | B15: 46214 | C15: C1050 | D15: North | E15: Website | F15: Electronics | G15: Wireless Earbuds | H15: 2 | I15: 2548.98 | J15: 0 | K15: 3719.79 | L15: 5097.96 | M15: Delivered | N15: 5 | O15: =I15*H15 | P15: =O15*(1-IF(J15="",0,J15)) | Q15: =P15-K15 | R15: =IF(M15="Delivered",1,0)
A16: ORD5012 | B16: 46215 | C16: C1020 | D16: North | E16: Mobile App | F16: Sports | G16: Yoga Mat | H16: 3 | I16: 943.95 | J16: 0 | K16: 1561.04 | L16: 2831.85 | M16: Delivered | N16: 3 | O16: =I16*H16 | P16: =O16*(1-IF(J16="",0,J16)) | Q16: =P16-K16 | R16: =IF(M16="Delivered",1,0)
... A20: ORD5016 | B20: 46219 | C20: C1027 | D20: Central | E20: Marketplace | F20: Fashion | G20: Casual Shirt | H20: 3 | I20: 1260.03 | J20: 0.1 | K20: 2506.73 | L20: 3402.08 | M20: Delivered | N20: 2 | O20: =I20*H20 | P20: =O20*(1-IF(J20="",0,J20)) | Q20: =P20-K20 | R20: =IF(M20="Delivered",1,0)
A21: ORD5017 | B21: 46220 | D21: North | E21: Marketplace | F21: Beauty | G21: Hair Dryer | H21: 1 | I21: 2133.03 | J21: 0.2 | K21: 1479.04 | L21: 1706.42 | M21: Cancelled | O21: =I21*H21 | P21: =O21*(1-IF(J21="",0,J21)) | Q21: =P21-K21 | R21: =IF(M21="Delivered",1,0)
A22: ORD5018 | B22: 46221 | C22: C1008 | D22: South | E22: Website | F22: Fashion | G22: Running Shoes | H22: 1 | I22: 2715.03 | J22: 0.1 | K22: 1659.41 | L22: 2443.53 | M22: Delivered | N22: 3 | O22: =I22*H22 | P22: =O22*(1-IF(J22="",0,J22)) | Q22: =P22-K22 | R22: =IF(M22="Delivered",1,0)
A23: ORD5019 | B23: 46222 | C23: C1025 | D23: Central | E23: Mobile App | F23: Fashion | G23: Backpack | H23: 1 | I23: 1842.03 | J23: 0.1 | K23: 915.08 | L23: 1657.83 | M23: Delivered | N23: 2 | O23: =I23*H23 | P23: =O23*(1-IF(J23="",0,J23)) | Q23: =P23-K23 | R23: =IF(M23="Delivered",1,0)
A24: ORD5020 | B24: 46223 | C24: C1045 | D24: Central | E24: Website | F24: Fashion | G24: Backpack | H24: 3 | I24: 1993.95 | J24: 0.1 | K24: 3034.94 | L24: 5383.67 | M24: Returned | O24: =I24*H24 | P24: =O24*(1-IF(J24="",0,J24)) | Q24: =P24-K24 | R24: =IF(M24="Delivered",1,0)
A25: ORD5021 | B25: 46224 | C25: C1026 | D25: West | E25: Website | F25: Electronics | G25: Bluetooth Speaker | H25: 2 | I25: 1745.03 | J25: 0.1 | K25: 1679.44 | L25: 3141.05 | M25: Delivered | N25: 5 | O25: =I25*H25 | P25: =O25*(1-IF(J25="",0,J25)) | Q25: =P25-K25 | R25: =IF(M25="Delivered",1,0)
A26: ORD5022 | B26: 46225 | C26: C1039 | D26: East | E26: Mobile App | F26: Home & Kitchen | G26: Bedsheet Set | H26: 1 | I26: 1528.98 | J26: 0.05 | K26: 1123.84 | L26: 1452.53 | M26: Delivered | N26: 5 | O26: =I26*H26 | P26: =O26*(1-IF(J26="",0,J26)) | Q26: =P26-K26 | R26: =IF(M26="Delivered",1,0)
A27: ORD5023 | B27: 46226 | C27: C1043 | D27: North | E27: Website | F27: Beauty | G27: Hair Dryer | H27: 2 | I27: 2133.03 | J27: 0.15 | K27: 3194.62 | L27: 3626.15 | M27: Delivered | N27: 5 | O27: =I27*H27 | P27: =O27*(1-IF(J27="",0,J27)) | Q27: =P27-K27 | R27: =IF(M27="Delivered",1,0)
A28: ORD5024 | B28: 46227 | C28: C1003 | D28: East | E28: Website | F28: Electronics | G28: Wireless Earbuds | H28: 1 | I28: 2623.95 | J28: 0.15 | K28: 1376.51 | L28: 2230.36 | M28: Delivered | N28: 2 | O28: =I28*H28 | P28: =O28*(1-IF(J28="",0,J28)) | Q28: =P28-K28 | R28: =IF(M28="Delivered",1,0)
A29: ORD5025 | B29: 46228 | C29: C1048 | D29: West | E29: Mobile App | F29: Beauty | G29: Perfume | H29: 2 | I29: 1678.95 | J29: 0 | K29: 2125.38 | L29: 3357.9 | M29: Delivered | N29: 2 | O29: =I29*H29 | P29: =O29*(1-IF(J29="",0,J29)) | Q29: =P29-K29 | R29: =IF(M29="Delivered",1,0)
A30: ORD5026 | B30: 46229 | C30: C1055 | D30: East | E30: Marketplace | F30: Fashion | G30: Running Shoes | H30: 1 | I30: 2715.03 | J30: 0.2 | K30: 1648.05 | L30: 2172.02 | M30: Delivered | N30: 2 | O30: =I30*H30 | P30: =O30*(1-IF(J30="",0,J30)) | Q30: =P30-K30 | R30: =IF(M30="Delivered",1,0)
A31: ORD5027 | B31: 46230 | C31: C1013 | D31: South | E31: Website | F31: Home & Kitchen | G31: Bedsheet Set | H31: 3 | I31: 1528.98 | J31: 0.2 | K31: 3331.99 | L31: 3669.55 | M31: Delivered | N31: 2 | O31: =I31*H31 | P31: =O31*(1-IF(J31="",0,J31)) | Q31: =P31-K31 | R31: =IF(M31="Delivered",1,0)
A32: ORD5028 | B32: 46231 | C32: C1050 | D32: West | E32: Marketplace | F32: Sports | G32: Cricket Kit | H32: 2 | I32: 3568.98 | J32: 0.15 | K32: 4880.89 | L32: 6067.27 | M32: Delivered | N32: 3 | O32: =I32*H32 | P32: =O32*(1-IF(J32="",0,J32)) | Q32: =P32-K32 | R32: =IF(M32="Delivered",1,0)
A33: ORD5029 | B33: 46204 | C33: C1002 | D33: South | E33: Marketplace | F33: Beauty | G33: Hair Dryer | H33: 1 | I33: 2199 | J33: 0.1 | K33: 1242.3 | L33: 1979.1 | M33: Delivered | N33: 1 | O33: =I33*H33 | P33: =O33*(1-IF(J33="",0,J33)) | Q33: =P33-K33 | R33: =IF(M33="Delivered",1,0)
A34: ORD5030 | B34: 46205 | C34: C1025 | D34: Central | E34: Website | F34: Beauty | G34: Skin Care Kit | H34: 1 | I34: 1018.98 | J34: 0.2 | K34: 499.65 | L34: 815.18 | M34: Delivered | N34: 3 | O34: =I34*H34 | P34: =O34*(1-IF(J34="",0,J34)) | Q34: =P34-K34 | R34: =IF(M34="Delivered",1,0)
A35: ORD5031 | B35: 46206 | C35: C1033 | D35: Central | E35: Marketplace | F35: Sports | G35: Yoga Mat | H35: 2 | I35: 943.95 | J35: 0.1 | K35: 1178.23 | L35: 1699.11 | M35: Delivered | N35: 1 | O35: =I35*H35 | P35: =O35*(1-IF(J35="",0,J35)) | Q35: =P35-K35 | R35: =IF(M35="Delivered",1,0)
A36: ORD5032 | B36: 46207 | C36: C1034 | D36: West | E36: Website | F36: Home & Kitchen | G36: Air Fryer | H36: 2 | I36: 5499 | J36: 0 | K36: 5695.91 | L36: 10998 | M36: Returned | O36: =I36*H36 | P36: =O36*(1-IF(J36="",0,J36)) | Q36: =P36-K36 | R36: =IF(M36="Delivered",1,0)
A37: ORD5033 | B37: 46208 | C37: C1008 | E37: Mobile App | F37: Fashion | G37: Casual Shirt | H37: 1 | I37: 1299 | J37: 0.2 | K37: 835.49 | L37: 1039.2 | M37: Delivered | N37: 2 | O37: =I37*H37 | P37: =O37*(1-IF(J37="",0,J37)) | Q37: =P37-K37 | R37: =IF(M37="Delivered",1,0)
A38: ORD5034 | B38: 46209 | C38: C1035 | D38: North | E38: Mobile App | F38: Fashion | G38: Backpack | H38: 2 | I38: 1936.98 | J38: 0 | K38: 2855.06 | L38: 3873.96 | M38: Returned | O38: =I38*H38 | P38: =O38*(1-IF(J38="",0,J38)) | Q38: =P38-K38 | R38: =IF(M38="Delivered",1,0)
A39: ORD5035 | B39: 46210 | C39: C1030 | D39: East | E39: Website | F39: Sports | G39: Yoga Mat | H39: 1 | I39: 899 | J39: 0.05 | K39: 488.85 | L39: 854.05 | M39: Delivered | N39: 3 | O39: =I39*H39 | P39: =O39*(1-IF(J39="",0,J39)) | Q39: =P39-K39 | R39: =IF(M39="Delivered",1,0)
A40: ORD5036 | B40: 46211 | C40: C1037 | D40: South | E40: Website | F40: Fashion | G40: Running Shoes | H40: 1 | I40: 2854.98 | J40: 0 | K40: 1784.64 | L40: 2854.98 | M40: Delivered | N40: 3 | O40: =I40*H40 | P40: =O40*(1-IF(J40="",0,J40)) | Q40: =P40-K40 | R40: =IF(M40="Delivered",1,0)
A41: ORD5037 | B41: 46212 | C41: C1009 | D41: North | E41: Website | F41: Home & Kitchen | G41: Air Fryer | H41: 1 | I41: 5773.95 | J41: 0.05 | K41: 3072.82 | L41: 5485.25 | M41: Delivered | N41: 4 | O41: =I41*H41 | P41: =O41*(1-IF(J41="",0,J41)) | Q41: =P41-K41 | R41: =IF(M41="Delivered",1,0)
A42: ORD5038 | B42: 46213 | C42: C1023 | D42: East | E42: Mobile App | F42: Electronics | G42: Bluetooth Speaker | H42: 4 | I42: 1888.95 | J42: 0.05 | K42: 5680.57 | L42: 7178.01 | M42: Delivered | N42: 4 | O42: =I42*H42 | P42: =O42*(1-IF(J42="",0,J42)) | Q42: =P42-K42 | R42: =IF(M42="Delivered",1,0)
A43: ORD5039 | B43: 46214 | C43: C1038 | D43: East | E43: Marketplace | F43: Sports | G43: Cricket Kit | H43: 2 | I43: 3394.03 | J43: 0 | K43: 3722.95 | L43: 6788.06 | M43: Delivered | N43: 5 | O43: =I43*H43 | P43: =O43*(1-IF(J43="",0,J43)) | Q43: =P43-K43 | R43: =IF(M43="Delivered",1,0)
A44: ORD5040 | B44: 46215 | C44: C1031 | D44: Central | E44: Mobile App | F44: Beauty | G44: Hair Dryer | H44: 2 | I44: 2133.03 | J44: 0.15 | K44: 2207.83 | L44: 3626.15 | M44: Delivered | N44: 1 | O44: =I44*H44 | P44: =O44*(1-IF(J44="",0,J44)) | Q44: =P44-K44 | R44: =IF(M44="Delivered",1,0)
...

Sheet Analysis
A1: ANALYSIS & KPI SUMMARY
A2: Use formulas, PivotTables or SUMIFS/COUNTIFS. Clearly define what is included in sales and rates.
A4: KPI | B4: Value | C4: Definition / notes | E4: Breakdown | F4: Net Sales (INR) | G4: Gross Profit (INR)
A5: Total records | B5: =COUNTA('Raw Data'!A5:A124) | C5: Count all rows, including cancelled and returned orders | E5: Region
A6: Unique Order IDs | B6: =SUMPRODUCT(('Raw Data'!A5:A124<>"")/COUNTIF('Raw Data'!A5:A124,'Raw Data'!A5:A124&"")) | C6: Count distinct IDs after identifying duplicate | E6: North | F6: =SUMIFS('Raw Data'!$P$5:$P$124,'Raw Data'!$D$5:$D$124,E6,'Raw Data'!$M$5:$M$124,"Delivered") | G6: =SUMIFS('Raw Data'!$Q$5:$Q$124,'Raw Data'!$D$5:$D$124,E6,'Raw Data'!$M$5:$M$124,"Delivered")
A7: Delivered orders | B7: =COUNTIF('Raw Data'!M5:M124,"Delivered") | C7: Status = Delivered | E7: South | F7: =SUMIFS('Raw Data'!$P$5:$P$124,'Raw Data'!$D$5:$D$124,E7,'Raw Data'!$M$5:$M$124,"Delivered") | G7: =SUMIFS('Raw Data'!$Q$5:$Q$124,'Raw Data'!$D$5:$D$124,E7,'Raw Data'!$M$5:$M$124,"Delivered")
A8: Return rate | B8: =COUNTIF('Raw Data'!M5:M124,"Returned")/COUNTA('Raw Data'!A5:A124) | C8: Returned orders ÷ total records; state if you use delivered-only denominator instead | E8: East | F8: =SUMIFS('Raw Data'!$P$5:$P$124,'Raw Data'!$D$5:$D$124,E8,'Raw Data'!$M$5:$M$124,"Delivered") | G8: =SUMIFS('Raw Data'!$Q$5:$Q$124,'Raw Data'!$D$5:$D$124,E8,'Raw Data'!$M$5:$M$124,"Delivered")
A9: Cancellation rate | B9: =COUNTIF('Raw Data'!M5:M124,"Cancelled")/COUNTA('Raw Data'!A5:A124) | C9: Cancelled orders ÷ total records | E9: West | F9: =SUMIFS('Raw Data'!$P$5:$P$124,'Raw Data'!$D$5:$D$124,E9,'Raw Data'!$M$5:$M$124,"Delivered") | G9: =SUMIFS('Raw Data'!$Q$5:$Q$124,'Raw Data'!$D$5:$D$124,E9,'Raw Data'!$M$5:$M$124,"Delivered")
A10: Net sales | B10: =SUMIFS('Raw Data'!P5:P124,'Raw Data'!M5:M124,"Delivered") | C10: Sum Net Sales for Delivered orders only | E10: Central | F10: =SUMIFS('Raw Data'!$P$5:$P$124,'Raw Data'!$D$5:$D$124,E10,'Raw Data'!$M$5:$M$124,"Delivered") | G10: =SUMIFS('Raw Data'!$Q$5:$Q$124,'Raw Data'!$D$5:$D$124,E10,'Raw Data'!$M$5:$M$124,"Delivered")
A11: Gross profit | B11: =SUMIFS('Raw Data'!Q5:Q124,'Raw Data'!M5:M124,"Delivered") | C11: Sum Gross Profit for Delivered orders only
A12: Gross margin | B12: =B11/B10 | C12: Gross profit ÷ delivered net sales | E12: Channel
A13: Average order value (AOV) | B13: =B10/B7 | C13: Delivered net sales ÷ delivered orders | E13: Website | F13: =SUMIFS('Raw Data'!$P$5:$P$124,'Raw Data'!$E$5:$E$124,E13,'Raw Data'!$M$5:$M$124,"Delivered") | G13: =SUMIFS('Raw Data'!$Q$5:$Q$124,'Raw Data'!$E$5:$E$124,E13,'Raw Data'!$M$5:$M$124,"Delivered")
A14: Missing Customer IDs | B14: =COUNTBLANK('Raw Data'!C5:C124) | C14: Count blank Customer ID | E14: Mobile App | F14: =SUMIFS('Raw Data'!$P$5:$P$124,'Raw Data'!$E$5:$E$124,E14,'Raw Data'!$M$5:$M$124,"Delivered") | G14: =SUMIFS('Raw Data'!$Q$5:$Q$124,'Raw Data'!$E$5:$E$124,E14,'Raw Data'!$M$5:$M$124,"Delivered")
A15: Missing Regions | B15: =COUNTBLANK('Raw Data'!D5:D124) | C15: Count blank Region | E15: Marketplace | F15: =SUMIFS('Raw Data'!$P$5:$P$124,'Raw Data'!$E$5:$E$124,E15,'Raw Data'!$M$5:$M$124,"Delivered") | G15: =SUMIFS('Raw Data'!$Q$5:$Q$124,'Raw Data'!$E$5:$E$124,E15,'Raw Data'!$M$5:$M$124,"Delivered")
A16: Missing Discounts | B16: =COUNTBLANK('Raw Data'!J5:J124) | C16: Count blank Discount %
A17: Duplicate Order IDs | B17: =COUNTA('Raw Data'!A5:A124)-SUMPRODUCT(1/COUNTIF('Raw Data'!A5:A124,'Raw Data'!A5:A124)) | C17: Count of rows beyond first occurrence for duplicate Order ID | E17: Category
E18: Electronics | F18: =SUMIFS('Raw Data'!$P$5:$P$124,'Raw Data'!$F$5:$F$124,E18,'Raw Data'!$M$5:$M$124,"Delivered") | G18: =SUMIFS('Raw Data'!$Q$5:$Q$124,'Raw Data'!$F$5:$F$124,E18,'Raw Data'!$M$5:$M$124,"Delivered")
E19: Home & Kitchen | F19: =SUMIFS('Raw Data'!$P$5:$P$124,'Raw Data'!$F$5:$F$124,E19,'Raw Data'!$M$5:$M$124,"Delivered") | G19: =SUMIFS('Raw Data'!$Q$5:$Q$124,'Raw Data'!$F$5:$F$124,E19,'Raw Data'!$M$5:$M$124,"Delivered")
F20: =SUMIFS('Raw Data'!$P$5:$P$124,'Raw Data'!$F$5:$F$124,E20,'Raw Data'!$M$5:$M$124,"Delivered") | G20: =SUMIFS('Raw Data'!$Q$5:$Q$124,'Raw Data'!$F$5:$F$124,E20,'Raw Data'!$M$5:$M$124,"Delivered")
F21: =SUMIFS('Raw Data'!$P$5:$P$124,'Raw Data'!$F$5:$F$124,E21,'Raw Data'!$M$5:$M$124,"Delivered") | G21: =SUMIFS('Raw Data'!$Q$5:$Q$124,'Raw Data'!$F$5:$F$124,E21,'Raw Data'!$M$5:$M$124,"Delivered")
F22: =SUMIFS('Raw Data'!$P$5:$P$124,'Raw Data'!$F$5:$F$124,E22,'Raw Data'!$M$5:$M$124,"Delivered") | G22: =SUMIFS('Raw Data'!$Q$5:$Q$124,'Raw Data'!$F$5:$F$124,E22,'Raw Data'!$M$5:$M$124,"Delivered")
A25: Business insights | B25: Write two actionable insights and one caveat. Mention the metric supporting each insight.
A29: Data-quality treatment | B29: Explain how you treated duplicate Order IDs and missing discount, region and customer values.

Sheet Answer Key
A1: ANSWER KEY — OPEN ONLY AFTER YOUR ATTEMPT
A3: Expected formulas / approach
A4: Gross Sales | B4: Unit Price × Quantity
A5: Net Sales | B5: Gross Sales × (1 − Discount); assume blank discount = 0% only if documented and flagged
A6: Gross Profit | B6: Net Sales − Cost. Report delivered-only sales/profit for this exercise.
A7: Delivered flag | B7: IF(Status="Delivered",1,0)
A8: Delivered net sales | B8: SUMIFS(Net Sales, Status, "Delivered")
A9: Return rate | B9: Returned rows ÷ all rows in this mock; alternative denominator acceptable if clearly defined.
A10: Cancellation rate | B10: Cancelled rows ÷ all rows in this mock.
A11: AOV | B11: Delivered net sales ÷ delivered order count.
A12: Duplicates | B12: Use COUNTIF to flag repeated Order IDs; investigate before removing. One duplicate ID occurs in two records.
A13: Missing fields | B13: Do not infer Customer ID or Region. Treat blank discount as 0 only as a stated assumption.
A14: Business interpretation | B14: Compare segments on delivered net sales and gross profit, with margin as a complementary metric. Avoid causal claims.
A16: Indicative results (under stated assumptions)
A17: Total records | B17: 120 | C17: rows
A18: Unique Order IDs | B18: 119 | C18: distinct IDs
A19: Delivered orders | B19: 104 | C19: orders
A20: Return rate | B20: 0.10833333 | C20: % of all records
A21: Cancellation rate | B21: 0.025 | C21: % of all records
A22: Delivered net sales | B22: 425867.85 | C22: INR
A23: Delivered gross profit | B23: 142709.11 | C23: INR
A24: Gross margin | B24: 0.33510187 | C24: %
A25: AOV | B25: 4094.8832 | C25: INR per delivered record
A26: Missing Customer IDs | B26: 3 | C26: rows
A27: Missing Regions | B27: 2 | C27: rows
A28: Missing Discounts | B28: 2 | C28: rows
A29: Duplicate rows beyond first | B29: 1 | C29: rows
A32: Delivered sales by segment
A33: Dimension | B33: Segment | C33: Net Sales (INR) | D33: Gross Profit (INR)
A34: Region | B34: North | C34: 128015.48 | D34: 41562.925
A35: Region | B35: South | C35: 69614.756 | D35: 24439.046
A36: Region | B36: East | C36: 79319.712 | D36: 24593.232
A37: Region | B37: West | C37: 98077.556 | D37: 32696.435
A38: Region | B38: Central | C38: 42154.215 | D38: 16994.995
A39: Channel | B39: Website | C39: 146886.04 | D39: 46822.188
A40: Channel | B40: Mobile App | C40: 204212.8 | D40: 71580.976
A41: Channel | B41: Marketplace | C41: 74769.019 | D41: 24305.949
A42: Category | B42: Electronics | C42: 78760.098 | D42: 25097.708
A43: Category | B43: Home & Kitchen | C43: 169467.81 | D43: 58965.511
A44: Category | B44: Fashion | C44: 65743.7 | D44: 21250.64
...
